Workbook

Sheet Rules
A1: Scotland Golf Trip 2026 — Stableford Competition Rules
B3: What is Stableford?
B4: Stableford is a points-based scoring format. Instead of counting total strokes (stroke play), you score POINTS on every hole based on how your net score compares to par. Highest total points wins — not lowest strokes. A blow-up hole only costs you the points for that hole (min. 0), so one bad hole can't wreck your whole round the way it can in stroke play. That makes it ideal for a trip with mixed handicaps and a few pints the night before.
B6: Format for this trip: Individual Net Stableford
B7: Each player competes as an individual (not teams). Each player's handicap strokes are applied to give everyone a fair chance regardless of ability — see 'Handicap Strokes' below.
B9: Points Table (per hole, based on NET score vs. Par)
B11: Net Score vs. Par | C11: Points
B12: 2 or more over par (net double bogey or worse) | C12: 0
B13: 1 over par (net bogey) | C13: 1
B14: Par (net) | C14: 2
B15: 1 under par (net birdie) | C15: 3
B16: 2 under par (net eagle) | C16: 4
B17: 3 under par (net albatross) | C17: 5
B19: Handicap Strokes — how many shots you get, and on which holes
B20: 1) Each player has a Handicap Index (see the Players tab) — this doesn't change during the trip.
B21: 2) Each course converts that Index into a Course Handicap using ITS OWN Slope Rating and Course Rating (that math is done for you on the Course Handicaps tab).
B22: 3) We're playing everyone off their own full Course Handicap against scratch (0) — no adjustment relative to the group. The Course Handicaps tab does this math and auto-fills each round's 'Crs Hcp' column.
B23: 4) Net score on a hole = Gross strokes taken − handicap strokes received on that hole.
B24: This workbook calculates all of this automatically — Course Handicaps tab feeds each round's 'Crs Hcp' column, which combines with Par, Stroke Index and gross scores to produce points. (Leven Links is the exception: no slope/rating was supplied, so enter Course Handicap manually there.)
B26: Winning the trip
B27: Each round is scored separately, then total Stableford points across all 4 rounds are added up on the Leaderboard tab. Most total points after 4 rounds wins. Round-by-round results are also worth calling out for daily bragging rights / side bets.
B29: Quick reference
B30: • Play the ball as it lies — this is a fun, honor-system trip, not a Rules of Golf exam. Use common sense for lost balls / unplayable lies (e.g. count it a double bogey net for points purposes and move on).
B31: • If you can't finish a hole, or it's clearly going to score 0 points, pick up and move to the next tee — that's normal practice in Stableford and speeds up play.
B32: • Ties on the Leaderboard: countback on the last round played, then last 9 holes of that round.
... B35: Stableford scoring rules — Wikipedia (en.wikipedia.org/wiki/Stableford), MyGolfSpy (mygolfspy.com/news-opinion/stableford-scoring-system), and bunkered.co.uk. Individual net Stableford format — USGA Committee Procedures (usga.org).

Sheet Players
A1: Players & Handicaps
A3: # | B3: Player | C3: Handicap Index | D3: Tees | E3: Notes
A4: 1 | B4: Paul | C4: 18.7 | D4: Senior
A5: 2 | B5: David | C5: 18.5 | D5: Senior
A6: 3 | B6: Jonathan | C6: 12 | D6: Standard Men's
A7: 4 | B7: Patrick | C7: 22.5 | D7: Standard Men's
A8: 5 | B8: Andrew | C8: 25.6 | D8: Standard Men's
A9: 6 | B9: Peter | C9: 18 | D9: Standard Men's
A10: 7 | B10: Fraser | C10: 14.9 | D10: Standard Men's
A11: 8 | B11: Colin | C11: 25.1 | D11: Standard Men's
B13: Yellow cells = editable. Update Handicap Index or Tees here if they change during the trip.

Sheet Course Handicaps
A1: Course Handicaps — calculated from GHIN Handicap Index (full Course Handicap, playing to scratch/0)
A2: Course Handicap = ROUND(Handicap Index × Slope/113 + (Course Rating − Par)). Everyone plays their own full Course Handicap against scratch (0) — no adjustment relative to the group. These columns (F–I) are linked automatically into each round's 'Crs Hcp' column.
A3: # | B3: Player | C3: Hcp Index | D3: Tee | E3: Category | F3: Old Course Course Hcp | G3: Eden Course Hcp | H3: Craigtoun Course Hcp | I3: Crail Course Hcp | J3: Old Course Playing Hcp | K3: Eden Playing Hcp | L3: Craigtoun Playing Hcp | M3: Crail Playing Hcp
A4: 1 | B4: =Players!B4 -> Paul | C4: =Players!C4 -> 18.7 | D4: =Players!D4 -> Senior | E4: =IF(D4="Senior","Senior","Standard") -> Senior | F4: =ROUND(C4*IF($E4="Senior",125,129)/113+IF($E4="Senior",69.9,71.4)-72,0) -> 19 | G4: =ROUND(C4*IF($E4="Senior",117,121)/113+IF($E4="Senior",67,68.9)-70,0) -> 16 | H4: =ROUND(C4*IF($E4="Senior",133,134)/113+IF($E4="Senior",70.6,72.7)-71,0) -> 22 | I4: =ROUND(C4*IF($E4="Senior",118,122)/113+IF($E4="Senior",67.6,69.7)-69,0) -> 18 | J4: =F4-MIN($F$4:$F$11) -> 6 | K4: =G4-MIN($G$4:$G$11) -> 4 | L4: =H4-MIN($H$4:$H$11) -> 6 | M4: =I4-MIN($I$4:$I$11) -> 4
A5: 2 | B5: =Players!B5 -> David | C5: =Players!C5 -> 18.5 | D5: =Players!D5 -> Senior | E5: =IF(D5="Senior","Senior","Standard") -> Senior | F5: =ROUND(C5*IF($E5="Senior",125,129)/113+IF($E5="Senior",69.9,71.4)-72,0) -> 18 | G5: =ROUND(C5*IF($E5="Senior",117,121)/113+IF($E5="Senior",67,68.9)-70,0) -> 16 | H5: =ROUND(C5*IF($E5="Senior",133,134)/113+IF($E5="Senior",70.6,72.7)-71,0) -> 21 | I5: =ROUND(C5*IF($E5="Senior",118,122)/113+IF($E5="Senior",67.6,69.7)-69,0) -> 18 | J5: =F5-MIN($F$4:$F$11) -> 5 | K5: =G5-MIN($G$4:$G$11) -> 4 | L5: =H5-MIN($H$4:$H$11) -> 5 | M5: =I5-MIN($I$4:$I$11) -> 4
A6: 3 | B6: =Players!B6 -> Jonathan | C6: =Players!C6 -> 12 | D6: =Players!D6 -> Standard Men's | E6: =IF(D6="Senior","Senior","Standard") -> Standard | F6: =ROUND(C6*IF($E6="Senior",125,129)/113+IF($E6="Senior",69.9,71.4)-72,0) -> 13 | G6: =ROUND(C6*IF($E6="Senior",117,121)/113+IF($E6="Senior",67,68.9)-70,0) -> 12 | H6: =ROUND(C6*IF($E6="Senior",133,134)/113+IF($E6="Senior",70.6,72.7)-71,0) -> 16 | I6: =ROUND(C6*IF($E6="Senior",118,122)/113+IF($E6="Senior",67.6,69.7)-69,0) -> 14 | J6: =F6-MIN($F$4:$F$11) -> 0 | K6: =G6-MIN($G$4:$G$11) -> 0 | L6: =H6-MIN($H$4:$H$11) -> 0 | M6: =I6-MIN($I$4:$I$11) -> 0
A7: 4 | B7: =Players!B7 -> Patrick | C7: =Players!C7 -> 22.5 | D7: =Players!D7 -> Standard Men's | E7: =IF(D7="Senior","Senior","Standard") -> Standard | F7: =ROUND(C7*IF($E7="Senior",125,129)/113+IF($E7="Senior",69.9,71.4)-72,0) -> 25 | G7: =ROUND(C7*IF($E7="Senior",117,121)/113+IF($E7="Senior",67,68.9)-70,0) -> 23 | H7: =ROUND(C7*IF($E7="Senior",133,134)/113+IF($E7="Senior",70.6,72.7)-71,0) -> 28 | I7: =ROUND(C7*IF($E7="Senior",118,122)/113+IF($E7="Senior",67.6,69.7)-69,0) -> 25 | J7: =F7-MIN($F$4:$F$11) -> 12 | K7: =G7-MIN($G$4:$G$11) -> 11 | L7: =H7-MIN($H$4:$H$11) -> 12 | M7: =I7-MIN($I$4:$I$11) -> 11
A8: 5 | B8: =Players!B8 -> Andrew | C8: =Players!C8 -> 25.6 | D8: =Players!D8 -> Standard Men's | E8: =IF(D8="Senior","Senior","Standard") -> Standard | F8: =ROUND(C8*IF($E8="Senior",125,129)/113+IF($E8="Senior",69.9,71.4)-72,0) -> 29 | G8: =ROUND(C8*IF($E8="Senior",117,121)/113+IF($E8="Senior",67,68.9)-70,0) -> 26 | H8: =ROUND(C8*IF($E8="Senior",133,134)/113+IF($E8="Senior",70.6,72.7)-71,0) -> 32 | I8: =ROUND(C8*IF($E8="Senior",118,122)/113+IF($E8="Senior",67.6,69.7)-69,0) -> 28 | J8: =F8-MIN($F$4:$F$11) -> 16 | K8: =G8-MIN($G$4:$G$11) -> 14 | L8: =H8-MIN($H$4:$H$11) -> 16 | M8: =I8-MIN($I$4:$I$11) -> 14
A9: 6 | B9: =Players!B9 -> Peter | C9: =Players!C9 -> 18 | D9: =Players!D9 -> Standard Men's | E9: =IF(D9="Senior","Senior","Standard") -> Standard | F9: =ROUND(C9*IF($E9="Senior",125,129)/113+IF($E9="Senior",69.9,71.4)-72,0) -> 20 | G9: =ROUND(C9*IF($E9="Senior",117,121)/113+IF($E9="Senior",67,68.9)-70,0) -> 18 | H9: =ROUND(C9*IF($E9="Senior",133,134)/113+IF($E9="Senior",70.6,72.7)-71,0) -> 23 | I9: =ROUND(C9*IF($E9="Senior",118,122)/113+IF($E9="Senior",67.6,69.7)-69,0) -> 20 | J9: =F9-MIN($F$4:$F$11) -> 7 | K9: =G9-MIN($G$4:$G$11) -> 6 | L9: =H9-MIN($H$4:$H$11) -> 7 | M9: =I9-MIN($I$4:$I$11) -> 6
A10: 7 | B10: =Players!B10 -> Fraser | C10: =Players!C10 -> 14.9 | D10: =Players!D10 -> Standard Men's | E10: =IF(D10="Senior","Senior","Standard") -> Standard | F10: =ROUND(C10*IF($E10="Senior",125,129)/113+IF($E10="Senior",69.9,71.4)-72,0) -> 16 | G10: =ROUND(C10*IF($E10="Senior",117,121)/113+IF($E10="Senior",67,68.9)-70,0) -> 15 | H10: =ROUND(C10*IF($E10="Senior",133,134)/113+IF($E10="Senior",70.6,72.7)-71,0) -> 19 | I10: =ROUND(C10*IF($E10="Senior",118,122)/113+IF($E10="Senior",67.6,69.7)-69,0) -> 17 | J10: =F10-MIN($F$4:$F$11) -> 3 | K10: =G10-MIN($G$4:$G$11) -> 3 | L10: =H10-MIN($H$4:$H$11) -> 3 | M10: =I10-MIN($I$4:$I$11) -> 3
A11: 8 | B11: =Players!B11 -> Colin | C11: =Players!C11 -> 25.1 | D11: =Players!D11 -> Standard Men's | E11: =IF(D11="Senior","Senior","Standard") -> Standard | F11: =ROUND(C11*IF($E11="Senior",125,129)/113+IF($E11="Senior",69.9,71.4)-72,0) -> 28 | G11: =ROUND(C11*IF($E11="Senior",117,121)/113+IF($E11="Senior",67,68.9)-70,0) -> 26 | H11: =ROUND(C11*IF($E11="Senior",133,134)/113+IF($E11="Senior",70.6,72.7)-71,0) -> 31 | I11: =ROUND(C11*IF($E11="Senior",118,122)/113+IF($E11="Senior",67.6,69.7)-69,0) -> 28 | J11: =F11-MIN($F$4:$F$11) -> 15 | K11: =G11-MIN($G$4:$G$11) -> 14 | L11: =H11-MIN($H$4:$H$11) -> 15 | M11: =I11-MIN($I$4:$I$11) -> 14
B13: Slope/Rating source: club-provided course cards (see chat). Leven Links not included — no slope/rating supplied; enter its Course Handicap manually on that tab.

Sheet Rd1 - Eden
A1: Round 1 — The Eden Course, St Andrews Links (Monday)
A2: Hole | B2: Crs Hcp | C2: 1 | D2: 2 | E2: 3 | F2: 4 | G2: 5 | H2: 6 | I2: 7 | J2: 8 | K2: 9 | L2: OUT | M2: 10 | N2: 11 | O2: 12 | P2: 13 | Q2: 14 | R2: 15 | S2: 16 | T2: 17 | U2: 18 | V2: IN | W2: TOTAL
A3: Par | C3: 4 | D3: 4 | E3: 4 | F3: 4 | G3: 3 | H3: 4 | I3: 4 | J3: 3 | K3: 5 | L3: =SUM(C3:K3) -> 35 | M3: 3 | N3: 4 | O3: 4 | P3: 4 | Q3: 4 | R3: 3 | S3: 5 | T3: 4 | U3: 4 | V3: =SUM(M3:U3) -> 35 | W3: =L3+V3 -> 70
A4: Stroke Index | C4: 11 | D4: 3 | E4: 8 | F4: 17 | G4: 15 | H4: 5 | I4: 13 | J4: 9 | K4: 1 | M4: 14 | N4: 7 | O4: 16 | P4: 2 | Q4: 10 | R4: 18 | S4: 6 | T4: 4 | U4: 12
A5: Paul — Gross | B5: ='Course Handicaps'!G4 -> 16 | C5: 4 | D5: 7 | E5: 6 | F5: 5 | G5: 4 | H5: 6 | I5: 5 | J5: 4 | K5: 5 | L5: =IF(COUNT(C5:K5)=0,"",SUM(C5:K5)) -> 46 | M5: 3 | N5: 5 | O5: 4 | P5: 4 | Q5: 4 | R5: 3 | S5: 5 | T5: 6 | U5: 4 | V5: =IF(COUNT(M5:U5)=0,"",SUM(M5:U5)) -> 38 | W5: =IF(AND(L5="",V5=""),"",SUM(L5,V5)) -> 84
A6: Paul — Strokes received | C6: =IF($B5="","",FLOOR($B5/18,1)+IF(MOD($B5,18)>=C$4,1,0)) -> 1 | D6: =IF($B5="","",FLOOR($B5/18,1)+IF(MOD($B5,18)>=D$4,1,0)) -> 1 | E6: =IF($B5="","",FLOOR($B5/18,1)+IF(MOD($B5,18)>=E$4,1,0)) -> 1 | F6: =IF($B5="","",FLOOR($B5/18,1)+IF(MOD($B5,18)>=F$4,1,0)) -> 0 | G6: =IF($B5="","",FLOOR($B5/18,1)+IF(MOD($B5,18)>=G$4,1,0)) -> 1 | H6: =IF($B5="","",FLOOR($B5/18,1)+IF(MOD($B5,18)>=H$4,1,0)) -> 1 | I6: =IF($B5="","",FLOOR($B5/18,1)+IF(MOD($B5,18)>=I$4,1,0)) -> 1 | J6: =IF($B5="","",FLOOR($B5/18,1)+IF(MOD($B5,18)>=J$4,1,0)) -> 1 | K6: =IF($B5="","",FLOOR($B5/18,1)+IF(MOD($B5,18)>=K$4,1,0)) -> 1 | L6: =IF(COUNT(C6:K6)=0,"",SUM(C6:K6)) -> 8 | M6: =IF($B5="","",FLOOR($B5/18,1)+IF(MOD($B5,18)>=M$4,1,0)) -> 1 | N6: =IF($B5="","",FLOOR($B5/18,1)+IF(MOD($B5,18)>=N$4,1,0)) -> 1 | O6: =IF($B5="","",FLOOR($B5/18,1)+IF(MOD($B5,18)>=O$4,1,0)) -> 1 | P6: =IF($B5="","",FLOOR($B5/18,1)+IF(MOD($B5,18)>=P$4,1,0)) -> 1 | Q6: =IF($B5="","",FLOOR($B5/18,1)+IF(MOD($B5,18)>=Q$4,1,0)) -> 1 | R6: =IF($B5="","",FLOOR($B5/18,1)+IF(MOD($B5,18)>=R$4,1,0)) -> 0 | S6: =IF($B5="","",FLOOR($B5/18,1)+IF(MOD($B5,18)>=S$4,1,0)) -> 1 | T6: =IF($B5="","",FLOOR($B5/18,1)+IF(MOD($B5,18)>=T$4,1,0)) -> 1 | U6: =IF($B5="","",FLOOR($B5/18,1)+IF(MOD($B5,18)>=U$4,1,0)) -> 1 | V6: =IF(COUNT(M6:U6)=0,"",SUM(M6:U6)) -> 8 | W6: =IF(AND(L6="",V6=""),"",SUM(L6,V6)) -> 16
A7: Paul — Pts | C7: =IF(C5="","",MAX(0,2-((C5-C6)-C$3))) -> 3 | D7: =IF(D5="","",MAX(0,2-((D5-D6)-D$3))) -> 0 | E7: =IF(E5="","",MAX(0,2-((E5-E6)-E$3))) -> 1 | F7: =IF(F5="","",MAX(0,2-((F5-F6)-F$3))) -> 1 | G7: =IF(G5="","",MAX(0,2-((G5-G6)-G$3))) -> 2 | H7: =IF(H5="","",MAX(0,2-((H5-H6)-H$3))) -> 1 | I7: =IF(I5="","",MAX(0,2-((I5-I6)-I$3))) -> 2 | J7: =IF(J5="","",MAX(0,2-((J5-J6)-J$3))) -> 2 | K7: =IF(K5="","",MAX(0,2-((K5-K6)-K$3))) -> 3 | L7: =SUM(C7:K7) -> 15 | M7: =IF(M5="","",MAX(0,2-((M5-M6)-M$3))) -> 3 | N7: =IF(N5="","",MAX(0,2-((N5-N6)-N$3))) -> 2 | O7: =IF(O5="","",MAX(0,2-((O5-O6)-O$3))) -> 3 | P7: =IF(P5="","",MAX(0,2-((P5-P6)-P$3))) -> 3 | Q7: =IF(Q5="","",MAX(0,2-((Q5-Q6)-Q$3))) -> 3 | R7: =IF(R5="","",MAX(0,2-((R5-R6)-R$3))) -> 2 | S7: =IF(S5="","",MAX(0,2-((S5-S6)-S$3))) -> 3 | T7: =IF(T5="","",MAX(0,2-((T5-T6)-T$3))) -> 1 | U7: =IF(U5="","",MAX(0,2-((U5-U6)-U$3))) -> 3 | V7: =SUM(M7:U7) -> 23 | W7: =L7+V7 -> 38
A8: David — Gross | B8: ='Course Handicaps'!G5 -> 16 | C8: 4 | D8: 5 | E8: 5 | F8: 3 | G8: 4 | H8: 5 | I8: 5 | J8: 4 | K8: 6 | L8: =IF(COUNT(C8:K8)=0,"",SUM(C8:K8)) -> 41 | M8: 5 | N8: 4 | O8: 3 | P8: 4 | Q8: 5 | R8: 4 | S8: 8 | T8: 5 | U8: 4 | V8: =IF(COUNT(M8:U8)=0,"",SUM(M8:U8)) -> 42 | W8: =IF(AND(L8="",V8=""),"",SUM(L8,V8)) -> 83
A9: David — Strokes received | C9: =IF($B8="","",FLOOR($B8/18,1)+IF(MOD($B8,18)>=C$4,1,0)) -> 1 | D9: =IF($B8="","",FLOOR($B8/18,1)+IF(MOD($B8,18)>=D$4,1,0)) -> 1 | E9: =IF($B8="","",FLOOR($B8/18,1)+IF(MOD($B8,18)>=E$4,1,0)) -> 1 | F9: =IF($B8="","",FLOOR($B8/18,1)+IF(MOD($B8,18)>=F$4,1,0)) -> 0 | G9: =IF($B8="","",FLOOR($B8/18,1)+IF(MOD($B8,18)>=G$4,1,0)) -> 1 | H9: =IF($B8="","",FLOOR($B8/18,1)+IF(MOD($B8,18)>=H$4,1,0)) -> 1 | I9: =IF($B8="","",FLOOR($B8/18,1)+IF(MOD($B8,18)>=I$4,1,0)) -> 1 | J9: =IF($B8="","",FLOOR($B8/18,1)+IF(MOD($B8,18)>=J$4,1,0)) -> 1 | K9: =IF($B8="","",FLOOR($B8/18,1)+IF(MOD($B8,18)>=K$4,1,0)) -> 1 | L9: =IF(COUNT(C9:K9)=0,"",SUM(C9:K9)) -> 8 | M9: =IF($B8="","",FLOOR($B8/18,1)+IF(MOD($B8,18)>=M$4,1,0)) -> 1 | N9: =IF($B8="","",FLOOR($B8/18,1)+IF(MOD($B8,18)>=N$4,1,0)) -> 1 | O9: =IF($B8="","",FLOOR($B8/18,1)+IF(MOD($B8,18)>=O$4,1,0)) -> 1 | P9: =IF($B8="","",FLOOR($B8/18,1)+IF(MOD($B8,18)>=P$4,1,0)) -> 1 | Q9: =IF($B8="","",FLOOR($B8/18,1)+IF(MOD($B8,18)>=Q$4,1,0)) -> 1 | R9: =IF($B8="","",FLOOR($B8/18,1)+IF(MOD($B8,18)>=R$4,1,0)) -> 0 | S9: =IF($B8="","",FLOOR($B8/18,1)+IF(MOD($B8,18)>=S$4,1,0)) -> 1 | T9: =IF($B8="","",FLOOR($B8/18,1)+IF(MOD($B8,18)>=T$4,1,0)) -> 1 | U9: =IF($B8="","",FLOOR($B8/18,1)+IF(MOD($B8,18)>=U$4,1,0)) -> 1 | V9: =IF(COUNT(M9:U9)=0,"",SUM(M9:U9)) -> 8 | W9: =IF(AND(L9="",V9=""),"",SUM(L9,V9)) -> 16
A10: David — Pts | C10: =IF(C8="","",MAX(0,2-((C8-C9)-C$3))) -> 3 | D10: =IF(D8="","",MAX(0,2-((D8-D9)-D$3))) -> 2 | E10: =IF(E8="","",MAX(0,2-((E8-E9)-E$3))) -> 2 | F10: =IF(F8="","",MAX(0,2-((F8-F9)-F$3))) -> 3 | G10: =IF(G8="","",MAX(0,2-((G8-G9)-G$3))) -> 2 | H10: =IF(H8="","",MAX(0,2-((H8-H9)-H$3))) -> 2 | I10: =IF(I8="","",MAX(0,2-((I8-I9)-I$3))) -> 2 | J10: =IF(J8="","",MAX(0,2-((J8-J9)-J$3))) -> 2 | K10: =IF(K8="","",MAX(0,2-((K8-K9)-K$3))) -> 2 | L10: =SUM(C10:K10) -> 20 | M10: =IF(M8="","",MAX(0,2-((M8-M9)-M$3))) -> 1 | N10: =IF(N8="","",MAX(0,2-((N8-N9)-N$3))) -> 3 | O10: =IF(O8="","",MAX(0,2-((O8-O9)-O$3))) -> 4 | P10: =IF(P8="","",MAX(0,2-((P8-P9)-P$3))) -> 3 | Q10: =IF(Q8="","",MAX(0,2-((Q8-Q9)-Q$3))) -> 2 | R10: =IF(R8="","",MAX(0,2-((R8-R9)-R$3))) -> 1 | S10: =IF(S8="","",MAX(0,2-((S8-S9)-S$3))) -> 0 | T10: =IF(T8="","",MAX(0,2-((T8-T9)-T$3))) -> 2 | U10: =IF(U8="","",MAX(0,2-((U8-U9)-U$3))) -> 3 | V10: =SUM(M10:U10) -> 19 | W10: =L10+V10 -> 39
A11: Jonathan — Gross | B11: ='Course Handicaps'!G6 -> 12 | C11: 5 | D11: 7 | E11: 5 | F11: 4 | G11: 3 | H11: 4 | I11: 4 | J11: 3 | K11: 5 | L11: =IF(COUNT(C11:K11)=0,"",SUM(C11:K11)) -> 40 | M11: 4 | N11: 4 | O11: 5 | P11: 4 | Q11: 5 | R11: 3 | S11: 7 | T11: 5 | U11: 5 | V11: =IF(COUNT(M11:U11)=0,"",SUM(M11:U11)) -> 42 | W11: =IF(AND(L11="",V11=""),"",SUM(L11,V11)) -> 82
A12: Jonathan — Strokes received | C12: =IF($B11="","",FLOOR($B11/18,1)+IF(MOD($B11,18)>=C$4,1,0)) -> 1 | D12: =IF($B11="","",FLOOR($B11/18,1)+IF(MOD($B11,18)>=D$4,1,0)) -> 1 | E12: =IF($B11="","",FLOOR($B11/18,1)+IF(MOD($B11,18)>=E$4,1,0)) -> 1 | F12: =IF($B11="","",FLOOR($B11/18,1)+IF(MOD($B11,18)>=F$4,1,0)) -> 0 | G12: =IF($B11="","",FLOOR($B11/18,1)+IF(MOD($B11,18)>=G$4,1,0)) -> 0 | H12: =IF($B11="","",FLOOR($B11/18,1)+IF(MOD($B11,18)>=H$4,1,0)) -> 1 | I12: =IF($B11="","",FLOOR($B11/18,1)+IF(MOD($B11,18)>=I$4,1,0)) -> 0 | J12: =IF($B11="","",FLOOR($B11/18,1)+IF(MOD($B11,18)>=J$4,1,0)) -> 1 | K12: =IF($B11="","",FLOOR($B11/18,1)+IF(MOD($B11,18)>=K$4,1,0)) -> 1 | L12: =IF(COUNT(C12:K12)=0,"",SUM(C12:K12)) -> 6 | M12: =IF($B11="","",FLOOR($B11/18,1)+IF(MOD($B11,18)>=M$4,1,0)) -> 0 | N12: =IF($B11="","",FLOOR($B11/18,1)+IF(MOD($B11,18)>=N$4,1,0)) -> 1 | O12: =IF($B11="","",FLOOR($B11/18,1)+IF(MOD($B11,18)>=O$4,1,0)) -> 0 | P12: =IF($B11="","",FLOOR($B11/18,1)+IF(MOD($B11,18)>=P$4,1,0)) -> 1 | Q12: =IF($B11="","",FLOOR($B11/18,1)+IF(MOD($B11,18)>=Q$4,1,0)) -> 1 | R12: =IF($B11="","",FLOOR($B11/18,1)+IF(MOD($B11,18)>=R$4,1,0)) -> 0 | S12: =IF($B11="","",FLOOR($B11/18,1)+IF(MOD($B11,18)>=S$4,1,0)) -> 1 | T12: =IF($B11="","",FLOOR($B11/18,1)+IF(MOD($B11,18)>=T$4,1,0)) -> 1 | U12: =IF($B11="","",FLOOR($B11/18,1)+IF(MOD($B11,18)>=U$4,1,0)) -> 1 | V12: =IF(COUNT(M12:U12)=0,"",SUM(M12:U12)) -> 6 | W12: =IF(AND(L12="",V12=""),"",SUM(L12,V12)) -> 12
A13: Jonathan — Pts | C13: =IF(C11="","",MAX(0,2-((C11-C12)-C$3))) -> 2 | D13: =IF(D11="","",MAX(0,2-((D11-D12)-D$3))) -> 0 | E13: =IF(E11="","",MAX(0,2-((E11-E12)-E$3))) -> 2 | F13: =IF(F11="","",MAX(0,2-((F11-F12)-F$3))) -> 2 | G13: =IF(G11="","",MAX(0,2-((G11-G12)-G$3))) -> 2 | H13: =IF(H11="","",MAX(0,2-((H11-H12)-H$3))) -> 3 | I13: =IF(I11="","",MAX(0,2-((I11-I12)-I$3))) -> 2 | J13: =IF(J11="","",MAX(0,2-((J11-J12)-J$3))) -> 3 | K13: =IF(K11="","",MAX(0,2-((K11-K12)-K$3))) -> 3 | L13: =SUM(C13:K13) -> 19 | M13: =IF(M11="","",MAX(0,2-((M11-M12)-M$3))) -> 1 | N13: =IF(N11="","",MAX(0,2-((N11-N12)-N$3))) -> 3 | O13: =IF(O11="","",MAX(0,2-((O11-O12)-O$3))) -> 1 | P13: =IF(P11="","",MAX(0,2-((P11-P12)-P$3))) -> 3 | Q13: =IF(Q11="","",MAX(0,2-((Q11-Q12)-Q$3))) -> 2 | R13: =IF(R11="","",MAX(0,2-((R11-R12)-R$3))) -> 2 | S13: =IF(S11="","",MAX(0,2-((S11-S12)-S$3))) -> 1 | T13: =IF(T11="","",MAX(0,2-((T11-T12)-T$3))) -> 2 | U13: =IF(U11="","",MAX(0,2-((U11-U12)-U$3))) -> 2 | V13: =SUM(M13:U13) -> 17 | W13: =L13+V13 -> 36
A14: Patrick — Gross | B14: ='Course Handicaps'!G7 -> 23 | C14: 6 | D14: 7 | E14: 6 | F14: 4 | G14: 2 | H14: 5 | I14: 6 | J14: 6 | K14: 6 | L14: =IF(COUNT(C14:K14)=0,"",SUM(C14:K14)) -> 48 | M14: 4 | N14: 5 | O14: 6 | P14: 6 | Q14: 6 | R14: 5 | S14: 5 | T14: 6 | U14: 5 | V14: =IF(COUNT(M14:U14)=0,"",SUM(M14:U14)) -> 48 | W14: =IF(AND(L14="",V14=""),"",SUM(L14,V14)) -> 96
A15: Patrick — Strokes received | C15: =IF($B14="","",FLOOR($B14/18,1)+IF(MOD($B14,18)>=C$4,1,0)) -> 1 | D15: =IF($B14="","",FLOOR($B14/18,1)+IF(MOD($B14,18)>=D$4,1,0)) -> 2 | E15: =IF($B14="","",FLOOR($B14/18,1)+IF(MOD($B14,18)>=E$4,1,0)) -> 1 | F15: =IF($B14="","",FLOOR($B14/18,1)+IF(MOD($B14,18)>=F$4,1,0)) -> 1 | G15: =IF($B14="","",FLOOR($B14/18,1)+IF(MOD($B14,18)>=G$4,1,0)) -> 1 | H15: =IF($B14="","",FLOOR($B14/18,1)+IF(MOD($B14,18)>=H$4,1,0)) -> 2 | I15: =IF($B14="","",FLOOR($B14/18,1)+IF(MOD($B14,18)>=I$4,1,0)) -> 1 | J15: =IF($B14="","",FLOOR($B14/18,1)+IF(MOD($B14,18)>=J$4,1,0)) -> 1 | K15: =IF($B14="","",FLOOR($B14/18,1)+IF(MOD($B14,18)>=K$4,1,0)) -> 2 | L15: =IF(COUNT(C15:K15)=0,"",SUM(C15:K15)) -> 12 | M15: =IF($B14="","",FLOOR($B14/18,1)+IF(MOD($B14,18)>=M$4,1,0)) -> 1 | N15: =IF($B14="","",FLOOR($B14/18,1)+IF(MOD($B14,18)>=N$4,1,0)) -> 1 | O15: =IF($B14="","",FLOOR($B14/18,1)+IF(MOD($B14,18)>=O$4,1,0)) -> 1 | P15: =IF($B14="","",FLOOR($B14/18,1)+IF(MOD($B14,18)>=P$4,1,0)) -> 2 | Q15: =IF($B14="","",FLOOR($B14/18,1)+IF(MOD($B14,18)>=Q$4,1,0)) -> 1 | R15: =IF($B14="","",FLOOR($B14/18,1)+IF(MOD($B14,18)>=R$4,1,0)) -> 1 | S15: =IF($B14="","",FLOOR($B14/18,1)+IF(MOD($B14,18)>=S$4,1,0)) -> 1 | T15: =IF($B14="","",FLOOR($B14/18,1)+IF(MOD($B14,18)>=T$4,1,0)) -> 2 | U15: =IF($B14="","",FLOOR($B14/18,1)+IF(MOD($B14,18)>=U$4,1,0)) -> 1 | V15: =IF(COUNT(M15:U15)=0,"",SUM(M15:U15)) -> 11 | W15: =IF(AND(L15="",V15=""),"",SUM(L15,V15)) -> 23
A16: Patrick — Pts | C16: =IF(C14="","",MAX(0,2-((C14-C15)-C$3))) -> 1 | D16: =IF(D14="","",MAX(0,2-((D14-D15)-D$3))) -> 1 | E16: =IF(E14="","",MAX(0,2-((E14-E15)-E$3))) -> 1 | F16: =IF(F14="","",MAX(0,2-((F14-F15)-F$3))) -> 3 | G16: =IF(G14="","",MAX(0,2-((G14-G15)-G$3))) -> 4 | H16: =IF(H14="","",MAX(0,2-((H14-H15)-H$3))) -> 3 | I16: =IF(I14="","",MAX(0,2-((I14-I15)-I$3))) -> 1 | J16: =IF(J14="","",MAX(0,2-((J14-J15)-J$3))) -> 0 | K16: =IF(K14="","",MAX(0,2-((K14-K15)-K$3))) -> 3 | L16: =SUM(C16:K16) -> 17 | M16: =IF(M14="","",MAX(0,2-((M14-M15)-M$3))) -> 2 | N16: =IF(N14="","",MAX(0,2-((N14-N15)-N$3))) -> 2 | O16: =IF(O14="","",MAX(0,2-((O14-O15)-O$3))) -> 1 | P16: =IF(P14="","",MAX(0,2-((P14-P15)-P$3))) -> 2 | Q16: =IF(Q14="","",MAX(0,2-((Q14-Q15)-Q$3))) -> 1 | R16: =IF(R14="","",MAX(0,2-((R14-R15)-R$3))) -> 1 | S16: =IF(S14="","",MAX(0,2-((S14-S15)-S$3))) -> 3 | T16: =IF(T14="","",MAX(0,2-((T14-T15)-T$3))) -> 2 | U16: =IF(U14="","",MAX(0,2-((U14-U15)-U$3))) -> 2 | V16: =SUM(M16:U16) -> 16 | W16: =L16+V16 -> 33
A17: Andrew — Gross | B17: ='Course Handicaps'!G8 -> 26 | C17: 4 | D17: 5 | E17: 5 | F17: 5 | G17: 5 | H17: 5 | I17: 6 | J17: 5 | K17: 6 | L17: =IF(COUNT(C17:K17)=0,"",SUM(C17:K17)) -> 46 | M17: 7 | N17: 7 | O17: 6 | P17: 6 | Q17: 4 | R17: 5 | S17: 8 | T17: 6 | U17: 6 | V17: =IF(COUNT(M17:U17)=0,"",SUM(M17:U17)) -> 55 | W17: =IF(AND(L17="",V17=""),"",SUM(L17,V17)) -> 101
A18: Andrew — Strokes received | C18: =IF($B17="","",FLOOR($B17/18,1)+IF(MOD($B17,18)>=C$4,1,0)) -> 1 | D18: =IF($B17="","",FLOOR($B17/18,1)+IF(MOD($B17,18)>=D$4,1,0)) -> 2 | E18: =IF($B17="","",FLOOR($B17/18,1)+IF(MOD($B17,18)>=E$4,1,0)) -> 2 | F18: =IF($B17="","",FLOOR($B17/18,1)+IF(MOD($B17,18)>=F$4,1,0)) -> 1 | G18: =IF($B17="","",FLOOR($B17/18,1)+IF(MOD($B17,18)>=G$4,1,0)) -> 1 | H18: =IF($B17="","",FLOOR($B17/18,1)+IF(MOD($B17,18)>=H$4,1,0)) -> 2 | I18: =IF($B17="","",FLOOR($B17/18,1)+IF(MOD($B17,18)>=I$4,1,0)) -> 1 | J18: =IF($B17="","",FLOOR($B17/18,1)+IF(MOD($B17,18)>=J$4,1,0)) -> 1 | K18: =IF($B17="","",FLOOR($B17/18,1)+IF(MOD($B17,18)>=K$4,1,0)) -> 2 | L18: =IF(COUNT(C18:K18)=0,"",SUM(C18:K18)) -> 13 | M18: =IF($B17="","",FLOOR($B17/18,1)+IF(MOD($B17,18)>=M$4,1,0)) -> 1 | N18: =IF($B17="","",FLOOR($B17/18,1)+IF(MOD($B17,18)>=N$4,1,0)) -> 2 | O18: =IF($B17="","",FLOOR($B17/18,1)+IF(MOD($B17,18)>=O$4,1,0)) -> 1 | P18: =IF($B17="","",FLOOR($B17/18,1)+IF(MOD($B17,18)>=P$4,1,0)) -> 2 | Q18: =IF($B17="","",FLOOR($B17/18,1)+IF(MOD($B17,18)>=Q$4,1,0)) -> 1 | R18: =IF($B17="","",FLOOR($B17/18,1)+IF(MOD($B17,18)>=R$4,1,0)) -> 1 | S18: =IF($B17="","",FLOOR($B17/18,1)+IF(MOD($B17,18)>=S$4,1,0)) -> 2 | T18: =IF($B17="","",FLOOR($B17/18,1)+IF(MOD($B17,18)>=T$4,1,0)) -> 2 | U18: =IF($B17="","",FLOOR($B17/18,1)+IF(MOD($B17,18)>=U$4,1,0)) -> 1 | V18: =IF(COUNT(M18:U18)=0,"",SUM(M18:U18)) -> 13 | W18: =IF(AND(L18="",V18=""),"",SUM(L18,V18)) -> 26
A19: Andrew — Pts | C19: =IF(C17="","",MAX(0,2-((C17-C18)-C$3))) -> 3 | D19: =IF(D17="","",MAX(0,2-((D17-D18)-D$3))) -> 3 | E19: =IF(E17="","",MAX(0,2-((E17-E18)-E$3))) -> 3 | F19: =IF(F17="","",MAX(0,2-((F17-F18)-F$3))) -> 2 | G19: =IF(G17="","",MAX(0,2-((G17-G18)-G$3))) -> 1 | H19: =IF(H17="","",MAX(0,2-((H17-H18)-H$3))) -> 3 | I19: =IF(I17="","",MAX(0,2-((I17-I18)-I$3))) -> 1 | J19: =IF(J17="","",MAX(0,2-((J17-J18)-J$3))) -> 1 | K19: =IF(K17="","",MAX(0,2-((K17-K18)-K$3))) -> 3 | L19: =SUM(C19:K19) -> 20 | M19: =IF(M17="","",MAX(0,2-((M17-M18)-M$3))) -> 0 | N19: =IF(N17="","",MAX(0,2-((N17-N18)-N$3))) -> 1 | O19: =IF(O17="","",MAX(0,2-((O17-O18)-O$3))) -> 1 | P19: =IF(P17="","",MAX(0,2-((P17-P18)-P$3))) -> 2 | Q19: =IF(Q17="","",MAX(0,2-((Q17-Q18)-Q$3))) -> 3 | R19: =IF(R17="","",MAX(0,2-((R17-R18)-R$3))) -> 1 | S19: =IF(S17="","",MAX(0,2-((S17-S18)-S$3))) -> 1 | T19: =IF(T17="","",MAX(0,2-((T17-T18)-T$3))) -> 2 | U19: =IF(U17="","",MAX(0,2-((U17-U18)-U$3))) -> 1 | V19: =SUM(M19:U19) -> 12 | W19: =L19+V19 -> 32
A20: Peter — Gross | B20: ='Course Handicaps'!G9 -> 18 | C20: 5 | D20: 6 | E20: 5 | F20: 5 | G20: 4 | H20: 4 | I20: 6 | J20: 5 | K20: 6 | L20: =IF(COUNT(C20:K20)=0,"",SUM(C20:K20)) -> 46 | M20: 1 | N20: 4 | O20: 6 | P20: 5 | Q20: 5 | R20: 4 | S20: 6 | T20: 7 | U20: 6 | V20: =IF(COUNT(M20:U20)=0,"",SUM(M20:U20)) -> 44 | W20: =IF(AND(L20="",V20=""),"",SUM(L20,V20)) -> 90
A21: Peter — Strokes received | C21: =IF($B20="","",FLOOR($B20/18,1)+IF(MOD($B20,18)>=C$4,1,0)) -> 1 | D21: =IF($B20="","",FLOOR($B20/18,1)+IF(MOD($B20,18)>=D$4,1,0)) -> 1 | E21: =IF($B20="","",FLOOR($B20/18,1)+IF(MOD($B20,18)>=E$4,1,0)) -> 1 | F21: =IF($B20="","",FLOOR($B20/18,1)+IF(MOD($B20,18)>=F$4,1,0)) -> 1 | G21: =IF($B20="","",FLOOR($B20/18,1)+IF(MOD($B20,18)>=G$4,1,0)) -> 1 | H21: =IF($B20="","",FLOOR($B20/18,1)+IF(MOD($B20,18)>=H$4,1,0)) -> 1 | I21: =IF($B20="","",FLOOR($B20/18,1)+IF(MOD($B20,18)>=I$4,1,0)) -> 1 | J21: =IF($B20="","",FLOOR($B20/18,1)+IF(MOD($B20,18)>=J$4,1,0)) -> 1 | K21: =IF($B20="","",FLOOR($B20/18,1)+IF(MOD($B20,18)>=K$4,1,0)) -> 1 | L21: =IF(COUNT(C21:K21)=0,"",SUM(C21:K21)) -> 9 | M21: =IF($B20="","",FLOOR($B20/18,1)+IF(MOD($B20,18)>=M$4,1,0)) -> 1 | N21: =IF($B20="","",FLOOR($B20/18,1)+IF(MOD($B20,18)>=N$4,1,0)) -> 1 | O21: =IF($B20="","",FLOOR($B20/18,1)+IF(MOD($B20,18)>=O$4,1,0)) -> 1 | P21: =IF($B20="","",FLOOR($B20/18,1)+IF(MOD($B20,18)>=P$4,1,0)) -> 1 | Q21: =IF($B20="","",FLOOR($B20/18,1)+IF(MOD($B20,18)>=Q$4,1,0)) -> 1 | R21: =IF($B20="","",FLOOR($B20/18,1)+IF(MOD($B20,18)>=R$4,1,0)) -> 1 | S21: =IF($B20="","",FLOOR($B20/18,1)+IF(MOD($B20,18)>=S$4,1,0)) -> 1 | T21: =IF($B20="","",FLOOR($B20/18,1)+IF(MOD($B20,18)>=T$4,1,0)) -> 1 | U21: =IF($B20="","",FLOOR($B20/18,1)+IF(MOD($B20,18)>=U$4,1,0)) -> 1 | V21: =IF(COUNT(M21:U21)=0,"",SUM(M21:U21)) -> 9 | W21: =IF(AND(L21="",V21=""),"",SUM(L21,V21)) -> 18
A22: Peter — Pts | C22: =IF(C20="","",MAX(0,2-((C20-C21)-C$3))) -> 2 | D22: =IF(D20="","",MAX(0,2-((D20-D21)-D$3))) -> 1 | E22: =IF(E20="","",MAX(0,2-((E20-E21)-E$3))) -> 2 | F22: =IF(F20="","",MAX(0,2-((F20-F21)-F$3))) -> 2 | G22: =IF(G20="","",MAX(0,2-((G20-G21)-G$3))) -> 2 | H22: =IF(H20="","",MAX(0,2-((H20-H21)-H$3))) -> 3 | I22: =IF(I20="","",MAX(0,2-((I20-I21)-I$3))) -> 1 | J22: =IF(J20="","",MAX(0,2-((J20-J21)-J$3))) -> 1 | K22: =IF(K20="","",MAX(0,2-((K20-K21)-K$3))) -> 2 | L22: =SUM(C22:K22) -> 16 | M22: =IF(M20="","",MAX(0,2-((M20-M21)-M$3))) -> 5 | N22: =IF(N20="","",MAX(0,2-((N20-N21)-N$3))) -> 3 | O22: =IF(O20="","",MAX(0,2-((O20-O21)-O$3))) -> 1 | P22: =IF(P20="","",MAX(0,2-((P20-P21)-P$3))) -> 2 | Q22: =IF(Q20="","",MAX(0,2-((Q20-Q21)-Q$3))) -> 2 | R22: =IF(R20="","",MAX(0,2-((R20-R21)-R$3))) -> 2 | S22: =IF(S20="","",MAX(0,2-((S20-S21)-S$3))) -> 2 | T22: =IF(T20="","",MAX(0,2-((T20-T21)-T$3))) -> 0 | U22: =IF(U20="","",MAX(0,2-((U20-U21)-U$3))) -> 1 | V22: =SUM(M22:U22) -> 18 | W22: =L22+V22 -> 34
A23: Fraser — Gross | B23: ='Course Handicaps'!G10 -> 15 | C23: 6 | D23: 6 | E23: 6 | F23: 4 | G23: 4 | H23: 4 | I23: 5 | J23: 4 | K23: 5 | L23: =IF(COUNT(C23:K23)=0,"",SUM(C23:K23)) -> 44 | M23: 4 | N23: 5 | O23: 4 | P23: 5 | Q23: 4 | R23: 4 | S23: 7 | T23: 5 | U23: 4 | V23: =IF(COUNT(M23:U23)=0,"",SUM(M23:U23)) -> 42 | W23: =IF(AND(L23="",V23=""),"",SUM(L23,V23)) -> 86
A24: Fraser — Strokes received | C24: =IF($B23="","",FLOOR($B23/18,1)+IF(MOD($B23,18)>=C$4,1,0)) -> 1 | D24: =IF($B23="","",FLOOR($B23/18,1)+IF(MOD($B23,18)>=D$4,1,0)) -> 1 | E24: =IF($B23="","",FLOOR($B23/18,1)+IF(MOD($B23,18)>=E$4,1,0)) -> 1 | F24: =IF($B23="","",FLOOR($B23/18,1)+IF(MOD($B23,18)>=F$4,1,0)) -> 0 | G24: =IF($B23="","",FLOOR($B23/18,1)+IF(MOD($B23,18)>=G$4,1,0)) -> 1 | H24: =IF($B23="","",FLOOR($B23/18,1)+IF(MOD($B23,18)>=H$4,1,0)) -> 1 | I24: =IF($B23="","",FLOOR($B23/18,1)+IF(MOD($B23,18)>=I$4,1,0)) -> 1 | J24: =IF($B23="","",FLOOR($B23/18,1)+IF(MOD($B23,18)>=J$4,1,0)) -> 1 | K24: =IF($B23="","",FLOOR($B23/18,1)+IF(MOD($B23,18)>=K$4,1,0)) -> 1 | L24: =IF(COUNT(C24:K24)=0,"",SUM(C24:K24)) -> 8 | M24: =IF($B23="","",FLOOR($B23/18,1)+IF(MOD($B23,18)>=M$4,1,0)) -> 1 | N24: =IF($B23="","",FLOOR($B23/18,1)+IF(MOD($B23,18)>=N$4,1,0)) -> 1 | O24: =IF($B23="","",FLOOR($B23/18,1)+IF(MOD($B23,18)>=O$4,1,0)) -> 0 | P24: =IF($B23="","",FLOOR($B23/18,1)+IF(MOD($B23,18)>=P$4,1,0)) -> 1 | Q24: =IF($B23="","",FLOOR($B23/18,1)+IF(MOD($B23,18)>=Q$4,1,0)) -> 1 | R24: =IF($B23="","",FLOOR($B23/18,1)+IF(MOD($B23,18)>=R$4,1,0)) -> 0 | S24: =IF($B23="","",FLOOR($B23/18,1)+IF(MOD($B23,18)>=S$4,1,0)) -> 1 | T24: =IF($B23="","",FLOOR($B23/18,1)+IF(MOD($B23,18)>=T$4,1,0)) -> 1 | U24: =IF($B23="","",FLOOR($B23/18,1)+IF(MOD($B23,18)>=U$4,1,0)) -> 1 | V24: =IF(COUNT(M24:U24)=0,"",SUM(M24:U24)) -> 7 | W24: =IF(AND(L24="",V24=""),"",SUM(L24,V24)) -> 15
A25: Fraser — Pts | C25: =IF(C23="","",MAX(0,2-((C23-C24)-C$3))) -> 1 | D25: =IF(D23="","",MAX(0,2-((D23-D24)-D$3))) -> 1 | E25: =IF(E23="","",MAX(0,2-((E23-E24)-E$3))) -> 1 | F25: =IF(F23="","",MAX(0,2-((F23-F24)-F$3))) -> 2 | G25: =IF(G23="","",MAX(0,2-((G23-G24)-G$3))) -> 2 | H25: =IF(H23="","",MAX(0,2-((H23-H24)-H$3))) -> 3 | I25: =IF(I23="","",MAX(0,2-((I23-I24)-I$3))) -> 2 | J25: =IF(J23="","",MAX(0,2-((J23-J24)-J$3))) -> 2 | K25: =IF(K23="","",MAX(0,2-((K23-K24)-K$3))) -> 3 | L25: =SUM(C25:K25) -> 17 | M25: =IF(M23="","",MAX(0,2-((M23-M24)-M$3))) -> 2 | N25: =IF(N23="","",MAX(0,2-((N23-N24)-N$3))) -> 2 | O25: =IF(O23="","",MAX(0,2-((O23-O24)-O$3))) -> 2 | P25: =IF(P23="","",MAX(0,2-((P23-P24)-P$3))) -> 2 | Q25: =IF(Q23="","",MAX(0,2-((Q23-Q24)-Q$3))) -> 3 | R25: =IF(R23="","",MAX(0,2-((R23-R24)-R$3))) -> 1 | S25: =IF(S23="","",MAX(0,2-((S23-S24)-S$3))) -> 1 | T25: =IF(T23="","",MAX(0,2-((T23-T24)-T$3))) -> 2 | U25: =IF(U23="","",MAX(0,2-((U23-U24)-U$3))) -> 3 | V25: =SUM(M25:U25) -> 18 | W25: =L25+V25 -> 35
A26: Colin — Gross | B26: ='Course Handicaps'!G11 -> 26 | C26: 7 | D26: 5 | E26: 5 | F26: 5 | G26: 4 | H26: 6 | I26: 7 | J26: 3 | K26: 6 | L26: =IF(COUNT(C26:K26)=0,"",SUM(C26:K26)) -> 48 | M26: 3 | N26: 5 | O26: 5 | P26: 7 | Q26: 6 | R26: 4 | S26: 6 | T26: 7 | U26: 5 | V26: =IF(COUNT(M26:U26)=0,"",SUM(M26:U26)) -> 48 | W26: =IF(AND(L26="",V26=""),"",SUM(L26,V26)) -> 96
A27: Colin — Strokes received | C27: =IF($B26="","",FLOOR($B26/18,1)+IF(MOD($B26,18)>=C$4,1,0)) -> 1 | D27: =IF($B26="","",FLOOR($B26/18,1)+IF(MOD($B26,18)>=D$4,1,0)) -> 2 | E27: =IF($B26="","",FLOOR($B26/18,1)+IF(MOD($B26,18)>=E$4,1,0)) -> 2 | F27: =IF($B26="","",FLOOR($B26/18,1)+IF(MOD($B26,18)>=F$4,1,0)) -> 1 | G27: =IF($B26="","",FLOOR($B26/18,1)+IF(MOD($B26,18)>=G$4,1,0)) -> 1 | H27: =IF($B26="","",FLOOR($B26/18,1)+IF(MOD($B26,18)>=H$4,1,0)) -> 2 | I27: =IF($B26="","",FLOOR($B26/18,1)+IF(MOD($B26,18)>=I$4,1,0)) -> 1 | J27: =IF($B26="","",FLOOR($B26/18,1)+IF(MOD($B26,18)>=J$4,1,0)) -> 1 | K27: =IF($B26="","",FLOOR($B26/18,1)+IF(MOD($B26,18)>=K$4,1,0)) -> 2 | L27: =IF(COUNT(C27:K27)=0,"",SUM(C27:K27)) -> 13 | M27: =IF($B26="","",FLOOR($B26/18,1)+IF(MOD($B26,18)>=M$4,1,0)) -> 1 | N27: =IF($B26="","",FLOOR($B26/18,1)+IF(MOD($B26,18)>=N$4,1,0)) -> 2 | O27: =IF($B26="","",FLOOR($B26/18,1)+IF(MOD($B26,18)>=O$4,1,0)) -> 1 | P27: =IF($B26="","",FLOOR($B26/18,1)+IF(MOD($B26,18)>=P$4,1,0)) -> 2 | Q27: =IF($B26="","",FLOOR($B26/18,1)+IF(MOD($B26,18)>=Q$4,1,0)) -> 1 | R27: =IF($B26="","",FLOOR($B26/18,1)+IF(MOD($B26,18)>=R$4,1,0)) -> 1 | S27: =IF($B26="","",FLOOR($B26/18,1)+IF(MOD($B26,18)>=S$4,1,0)) -> 2 | T27: =IF($B26="","",FLOOR($B26/18,1)+IF(MOD($B26,18)>=T$4,1,0)) -> 2 | U27: =IF($B26="","",FLOOR($B26/18,1)+IF(MOD($B26,18)>=U$4,1,0)) -> 1 | V27: =IF(COUNT(M27:U27)=0,"",SUM(M27:U27)) -> 13 | W27: =IF(AND(L27="",V27=""),"",SUM(L27,V27)) -> 26
A28: Colin — Pts | C28: =IF(C26="","",MAX(0,2-((C26-C27)-C$3))) -> 0 | D28: =IF(D26="","",MAX(0,2-((D26-D27)-D$3))) -> 3 | E28: =IF(E26="","",MAX(0,2-((E26-E27)-E$3))) -> 3 | F28: =IF(F26="","",MAX(0,2-((F26-F27)-F$3))) -> 2 | G28: =IF(G26="","",MAX(0,2-((G26-G27)-G$3))) -> 2 | H28: =IF(H26="","",MAX(0,2-((H26-H27)-H$3))) -> 2 | I28: =IF(I26="","",MAX(0,2-((I26-I27)-I$3))) -> 0 | J28: =IF(J26="","",MAX(0,2-((J26-J27)-J$3))) -> 3 | K28: =IF(K26="","",MAX(0,2-((K26-K27)-K$3))) -> 3 | L28: =SUM(C28:K28) -> 18 | M28: =IF(M26="","",MAX(0,2-((M26-M27)-M$3))) -> 3 | N28: =IF(N26="","",MAX(0,2-((N26-N27)-N$3))) -> 3 | O28: =IF(O26="","",MAX(0,2-((O26-O27)-O$3))) -> 2 | P28: =IF(P26="","",MAX(0,2-((P26-P27)-P$3))) -> 1 | Q28: =IF(Q26="","",MAX(0,2-((Q26-Q27)-Q$3))) -> 1 | R28: =IF(R26="","",MAX(0,2-((R26-R27)-R$3))) -> 2 | S28: =IF(S26="","",MAX(0,2-((S26-S27)-S$3))) -> 3 | T28: =IF(T26="","",MAX(0,2-((T26-T27)-T$3))) -> 1 | U28: =IF(U26="","",MAX(0,2-((U26-U27)-U$3))) -> 2 | V28: =SUM(M28:U28) -> 18 | W28: =L28+V28 -> 36
A30: Yellow = fill in: Par & Stroke Index from the course scorecard, Gross = strokes per hole. Crs Hcp (green) is auto-linked from the Course Handicaps tab — update handicaps there, not here. "Strokes received" and "Pts" rows calculate automatically.

Sheet Rd2 - Old Course
A1: Round 2 — The Old Course, St Andrews Links (Tuesday)
A2: Hole | B2: Crs Hcp | C2: 1 | D2: 2 | E2: 3 | F2: 4 | G2: 5 | H2: 6 | I2: 7 | J2: 8 | K2: 9 | L2: OUT | M2: 10 | N2: 11 | O2: 12 | P2: 13 | Q2: 14 | R2: 15 | S2: 16 | T2: 17 | U2: 18 | V2: IN | W2: TOTAL
A3: Par | L3: =SUM(C3:K3) -> 0 | V3: =SUM(M3:U3) -> 0 | W3: =L3+V3 -> 0
A4: Stroke Index
A5: Paul — Gross | B5: ='Course Handicaps'!F4 -> 19 | L5: =IF(COUNT(C5:K5)=0,"",SUM(C5:K5)) | V5: =IF(COUNT(M5:U5)=0,"",SUM(M5:U5)) | W5: =IF(AND(L5="",V5=""),"",SUM(L5,V5))
A6: Paul — Strokes received | C6: =IF($B5="","",FLOOR($B5/18,1)+IF(MOD($B5,18)>=C$4,1,0)) -> 2 | D6: =IF($B5="","",FLOOR($B5/18,1)+IF(MOD($B5,18)>=D$4,1,0)) -> 2 | E6: =IF($B5="","",FLOOR($B5/18,1)+IF(MOD($B5,18)>=E$4,1,0)) -> 2 | F6: =IF($B5="","",FLOOR($B5/18,1)+IF(MOD($B5,18)>=F$4,1,0)) -> 2 | G6: =IF($B5="","",FLOOR($B5/18,1)+IF(MOD($B5,18)>=G$4,1,0)) -> 2 | H6: =IF($B5="","",FLOOR($B5/18,1)+IF(MOD($B5,18)>=H$4,1,0)) -> 2 | I6: =IF($B5="","",FLOOR($B5/18,1)+IF(MOD($B5,18)>=I$4,1,0)) -> 2 | J6: =IF($B5="","",FLOOR($B5/18,1)+IF(MOD($B5,18)>=J$4,1,0)) -> 2 | K6: =IF($B5="","",FLOOR($B5/18,1)+IF(MOD($B5,18)>=K$4,1,0)) -> 2 | L6: =IF(COUNT(C6:K6)=0,"",SUM(C6:K6)) -> 18 | M6: =IF($B5="","",FLOOR($B5/18,1)+IF(MOD($B5,18)>=M$4,1,0)) -> 2 | N6: =IF($B5="","",FLOOR($B5/18,1)+IF(MOD($B5,18)>=N$4,1,0)) -> 2 | O6: =IF($B5="","",FLOOR($B5/18,1)+IF(MOD($B5,18)>=O$4,1,0)) -> 2 | P6: =IF($B5="","",FLOOR($B5/18,1)+IF(MOD($B5,18)>=P$4,1,0)) -> 2 | Q6: =IF($B5="","",FLOOR($B5/18,1)+IF(MOD($B5,18)>=Q$4,1,0)) -> 2 | R6: =IF($B5="","",FLOOR($B5/18,1)+IF(MOD($B5,18)>=R$4,1,0)) -> 2 | S6: =IF($B5="","",FLOOR($B5/18,1)+IF(MOD($B5,18)>=S$4,1,0)) -> 2 | T6: =IF($B5="","",FLOOR($B5/18,1)+IF(MOD($B5,18)>=T$4,1,0)) -> 2 | U6: =IF($B5="","",FLOOR($B5/18,1)+IF(MOD($B5,18)>=U$4,1,0)) -> 2 | V6: =IF(COUNT(M6:U6)=0,"",SUM(M6:U6)) -> 18 | W6: =IF(AND(L6="",V6=""),"",SUM(L6,V6)) -> 36
A7: Paul — Pts | C7: =IF(C5="","",MAX(0,2-((C5-C6)-C$3))) | D7: =IF(D5="","",MAX(0,2-((D5-D6)-D$3))) | E7: =IF(E5="","",MAX(0,2-((E5-E6)-E$3))) | F7: =IF(F5="","",MAX(0,2-((F5-F6)-F$3))) | G7: =IF(G5="","",MAX(0,2-((G5-G6)-G$3))) | H7: =IF(H5="","",MAX(0,2-((H5-H6)-H$3))) | I7: =IF(I5="","",MAX(0,2-((I5-I6)-I$3))) | J7: =IF(J5="","",MAX(0,2-((J5-J6)-J$3))) | K7: =IF(K5="","",MAX(0,2-((K5-K6)-K$3))) | L7: =SUM(C7:K7) -> 0 | M7: =IF(M5="","",MAX(0,2-((M5-M6)-M$3))) | N7: =IF(N5="","",MAX(0,2-((N5-N6)-N$3))) | O7: =IF(O5="","",MAX(0,2-((O5-O6)-O$3))) | P7: =IF(P5="","",MAX(0,2-((P5-P6)-P$3))) | Q7: =IF(Q5="","",MAX(0,2-((Q5-Q6)-Q$3))) | R7: =IF(R5="","",MAX(0,2-((R5-R6)-R$3))) | S7: =IF(S5="","",MAX(0,2-((S5-S6)-S$3))) | T7: =IF(T5="","",MAX(0,2-((T5-T6)-T$3))) | U7: =IF(U5="","",MAX(0,2-((U5-U6)-U$3))) | V7: =SUM(M7:U7) -> 0 | W7: =L7+V7 -> 0
A8: David — Gross | B8: ='Course Handicaps'!F5 -> 18 | L8: =IF(COUNT(C8:K8)=0,"",SUM(C8:K8)) | V8: =IF(COUNT(M8:U8)=0,"",SUM(M8:U8)) | W8: =IF(AND(L8="",V8=""),"",SUM(L8,V8))
A9: David — Strokes received | C9: =IF($B8="","",FLOOR($B8/18,1)+IF(MOD($B8,18)>=C$4,1,0)) -> 2 | D9: =IF($B8="","",FLOOR($B8/18,1)+IF(MOD($B8,18)>=D$4,1,0)) -> 2 | E9: =IF($B8="","",FLOOR($B8/18,1)+IF(MOD($B8,18)>=E$4,1,0)) -> 2 | F9: =IF($B8="","",FLOOR($B8/18,1)+IF(MOD($B8,18)>=F$4,1,0)) -> 2 | G9: =IF($B8="","",FLOOR($B8/18,1)+IF(MOD($B8,18)>=G$4,1,0)) -> 2 | H9: =IF($B8="","",FLOOR($B8/18,1)+IF(MOD($B8,18)>=H$4,1,0)) -> 2 | I9: =IF($B8="","",FLOOR($B8/18,1)+IF(MOD($B8,18)>=I$4,1,0)) -> 2 | J9: =IF($B8="","",FLOOR($B8/18,1)+IF(MOD($B8,18)>=J$4,1,0)) -> 2 | K9: =IF($B8="","",FLOOR($B8/18,1)+IF(MOD($B8,18)>=K$4,1,0)) -> 2 | L9: =IF(COUNT(C9:K9)=0,"",SUM(C9:K9)) -> 18 | M9: =IF($B8="","",FLOOR($B8/18,1)+IF(MOD($B8,18)>=M$4,1,0)) -> 2 | N9: =IF($B8="","",FLOOR($B8/18,1)+IF(MOD($B8,18)>=N$4,1,0)) -> 2 | O9: =IF($B8="","",FLOOR($B8/18,1)+IF(MOD($B8,18)>=O$4,1,0)) -> 2 | P9: =IF($B8="","",FLOOR($B8/18,1)+IF(MOD($B8,18)>=P$4,1,0)) -> 2 | Q9: =IF($B8="","",FLOOR($B8/18,1)+IF(MOD($B8,18)>=Q$4,1,0)) -> 2 | R9: =IF($B8="","",FLOOR($B8/18,1)+IF(MOD($B8,18)>=R$4,1,0)) -> 2 | S9: =IF($B8="","",FLOOR($B8/18,1)+IF(MOD($B8,18)>=S$4,1,0)) -> 2 | T9: =IF($B8="","",FLOOR($B8/18,1)+IF(MOD($B8,18)>=T$4,1,0)) -> 2 | U9: =IF($B8="","",FLOOR($B8/18,1)+IF(MOD($B8,18)>=U$4,1,0)) -> 2 | V9: =IF(COUNT(M9:U9)=0,"",SUM(M9:U9)) -> 18 | W9: =IF(AND(L9="",V9=""),"",SUM(L9,V9)) -> 36
A10: David — Pts | C10: =IF(C8="","",MAX(0,2-((C8-C9)-C$3))) | D10: =IF(D8="","",MAX(0,2-((D8-D9)-D$3))) | E10: =IF(E8="","",MAX(0,2-((E8-E9)-E$3))) | F10: =IF(F8="","",MAX(0,2-((F8-F9)-F$3))) | G10: =IF(G8="","",MAX(0,2-((G8-G9)-G$3))) | H10: =IF(H8="","",MAX(0,2-((H8-H9)-H$3))) | I10: =IF(I8="","",MAX(0,2-((I8-I9)-I$3))) | J10: =IF(J8="","",MAX(0,2-((J8-J9)-J$3))) | K10: =IF(K8="","",MAX(0,2-((K8-K9)-K$3))) | L10: =SUM(C10:K10) -> 0 | M10: =IF(M8="","",MAX(0,2-((M8-M9)-M$3))) | N10: =IF(N8="","",MAX(0,2-((N8-N9)-N$3))) | O10: =IF(O8="","",MAX(0,2-((O8-O9)-O$3))) | P10: =IF(P8="","",MAX(0,2-((P8-P9)-P$3))) | Q10: =IF(Q8="","",MAX(0,2-((Q8-Q9)-Q$3))) | R10: =IF(R8="","",MAX(0,2-((R8-R9)-R$3))) | S10: =IF(S8="","",MAX(0,2-((S8-S9)-S$3))) | T10: =IF(T8="","",MAX(0,2-((T8-T9)-T$3))) | U10: =IF(U8="","",MAX(0,2-((U8-U9)-U$3))) | V10: =SUM(M10:U10) -> 0 | W10: =L10+V10 -> 0
A11: Jonathan — Gross | B11: ='Course Handicaps'!F6 -> 13 | L11: =IF(COUNT(C11:K11)=0,"",SUM(C11:K11)) | V11: =IF(COUNT(M11:U11)=0,"",SUM(M11:U11)) | W11: =IF(AND(L11="",V11=""),"",SUM(L11,V11))
A12: Jonathan — Strokes received | C12: =IF($B11="","",FLOOR($B11/18,1)+IF(MOD($B11,18)>=C$4,1,0)) -> 1 | D12: =IF($B11="","",FLOOR($B11/18,1)+IF(MOD($B11,18)>=D$4,1,0)) -> 1 | E12: =IF($B11="","",FLOOR($B11/18,1)+IF(MOD($B11,18)>=E$4,1,0)) -> 1 | F12: =IF($B11="","",FLOOR($B11/18,1)+IF(MOD($B11,18)>=F$4,1,0)) -> 1 | G12: =IF($B11="","",FLOOR($B11/18,1)+IF(MOD($B11,18)>=G$4,1,0)) -> 1 | H12: =IF($B11="","",FLOOR($B11/18,1)+IF(MOD($B11,18)>=H$4,1,0)) -> 1 | I12: =IF($B11="","",FLOOR($B11/18,1)+IF(MOD($B11,18)>=I$4,1,0)) -> 1 | J12: =IF($B11="","",FLOOR($B11/18,1)+IF(MOD($B11,18)>=J$4,1,0)) -> 1 | K12: =IF($B11="","",FLOOR($B11/18,1)+IF(MOD($B11,18)>=K$4,1,0)) -> 1 | L12: =IF(COUNT(C12:K12)=0,"",SUM(C12:K12)) -> 9 | M12: =IF($B11="","",FLOOR($B11/18,1)+IF(MOD($B11,18)>=M$4,1,0)) -> 1 | N12: =IF($B11="","",FLOOR($B11/18,1)+IF(MOD($B11,18)>=N$4,1,0)) -> 1 | O12: =IF($B11="","",FLOOR($B11/18,1)+IF(MOD($B11,18)>=O$4,1,0)) -> 1 | P12: =IF($B11="","",FLOOR($B11/18,1)+IF(MOD($B11,18)>=P$4,1,0)) -> 1 | Q12: =IF($B11="","",FLOOR($B11/18,1)+IF(MOD($B11,18)>=Q$4,1,0)) -> 1 | R12: =IF($B11="","",FLOOR($B11/18,1)+IF(MOD($B11,18)>=R$4,1,0)) -> 1 | S12: =IF($B11="","",FLOOR($B11/18,1)+IF(MOD($B11,18)>=S$4,1,0)) -> 1 | T12: =IF($B11="","",FLOOR($B11/18,1)+IF(MOD($B11,18)>=T$4,1,0)) -> 1 | U12: =IF($B11="","",FLOOR($B11/18,1)+IF(MOD($B11,18)>=U$4,1,0)) -> 1 | V12: =IF(COUNT(M12:U12)=0,"",SUM(M12:U12)) -> 9 | W12: =IF(AND(L12="",V12=""),"",SUM(L12,V12)) -> 18
A13: Jonathan — Pts | C13: =IF(C11="","",MAX(0,2-((C11-C12)-C$3))) | D13: =IF(D11="","",MAX(0,2-((D11-D12)-D$3))) | E13: =IF(E11="","",MAX(0,2-((E11-E12)-E$3))) | F13: =IF(F11="","",MAX(0,2-((F11-F12)-F$3))) | G13: =IF(G11="","",MAX(0,2-((G11-G12)-G$3))) | H13: =IF(H11="","",MAX(0,2-((H11-H12)-H$3))) | I13: =IF(I11="","",MAX(0,2-((I11-I12)-I$3))) | J13: =IF(J11="","",MAX(0,2-((J11-J12)-J$3))) | K13: =IF(K11="","",MAX(0,2-((K11-K12)-K$3))) | L13: =SUM(C13:K13) -> 0 | M13: =IF(M11="","",MAX(0,2-((M11-M12)-M$3))) | N13: =IF(N11="","",MAX(0,2-((N11-N12)-N$3))) | O13: =IF(O11="","",MAX(0,2-((O11-O12)-O$3))) | P13: =IF(P11="","",MAX(0,2-((P11-P12)-P$3))) | Q13: =IF(Q11="","",MAX(0,2-((Q11-Q12)-Q$3))) | R13: =IF(R11="","",MAX(0,2-((R11-R12)-R$3))) | S13: =IF(S11="","",MAX(0,2-((S11-S12)-S$3))) | T13: =IF(T11="","",MAX(0,2-((T11-T12)-T$3))) | U13: =IF(U11="","",MAX(0,2-((U11-U12)-U$3))) | V13: =SUM(M13:U13) -> 0 | W13: =L13+V13 -> 0
A14: Patrick — Gross | B14: ='Course Handicaps'!F7 -> 25 | L14: =IF(COUNT(C14:K14)=0,"",SUM(C14:K14)) | V14: =IF(COUNT(M14:U14)=0,"",SUM(M14:U14)) | W14: =IF(AND(L14="",V14=""),"",SUM(L14,V14))
A15: Patrick — Strokes received | C15: =IF($B14="","",FLOOR($B14/18,1)+IF(MOD($B14,18)>=C$4,1,0)) -> 2 | D15: =IF($B14="","",FLOOR($B14/18,1)+IF(MOD($B14,18)>=D$4,1,0)) -> 2 | E15: =IF($B14="","",FLOOR($B14/18,1)+IF(MOD($B14,18)>=E$4,1,0)) -> 2 | F15: =IF($B14="","",FLOOR($B14/18,1)+IF(MOD($B14,18)>=F$4,1,0)) -> 2 | G15: =IF($B14="","",FLOOR($B14/18,1)+IF(MOD($B14,18)>=G$4,1,0)) -> 2 | H15: =IF($B14="","",FLOOR($B14/18,1)+IF(MOD($B14,18)>=H$4,1,0)) -> 2 | I15: =IF($B14="","",FLOOR($B14/18,1)+IF(MOD($B14,18)>=I$4,1,0)) -> 2 | J15: =IF($B14="","",FLOOR($B14/18,1)+IF(MOD($B14,18)>=J$4,1,0)) -> 2 | K15: =IF($B14="","",FLOOR($B14/18,1)+IF(MOD($B14,18)>=K$4,1,0)) -> 2 | L15: =IF(COUNT(C15:K15)=0,"",SUM(C15:K15)) -> 18 | M15: =IF($B14="","",FLOOR($B14/18,1)+IF(MOD($B14,18)>=M$4,1,0)) -> 2 | N15: =IF($B14="","",FLOOR($B14/18,1)+IF(MOD($B14,18)>=N$4,1,0)) -> 2 | O15: =IF($B14="","",FLOOR($B14/18,1)+IF(MOD($B14,18)>=O$4,1,0)) -> 2 | P15: =IF($B14="","",FLOOR($B14/18,1)+IF(MOD($B14,18)>=P$4,1,0)) -> 2 | Q15: =IF($B14="","",FLOOR($B14/18,1)+IF(MOD($B14,18)>=Q$4,1,0)) -> 2 | R15: =IF($B14="","",FLOOR($B14/18,1)+IF(MOD($B14,18)>=R$4,1,0)) -> 2 | S15: =IF($B14="","",FLOOR($B14/18,1)+IF(MOD($B14,18)>=S$4,1,0)) -> 2 | T15: =IF($B14="","",FLOOR($B14/18,1)+IF(MOD($B14,18)>=T$4,1,0)) -> 2 | U15: =IF($B14="","",FLOOR($B14/18,1)+IF(MOD($B14,18)>=U$4,1,0)) -> 2 | V15: =IF(COUNT(M15:U15)=0,"",SUM(M15:U15)) -> 18 | W15: =IF(AND(L15="",V15=""),"",SUM(L15,V15)) -> 36
A16: Patrick — Pts | C16: =IF(C14="","",MAX(0,2-((C14-C15)-C$3))) | D16: =IF(D14="","",MAX(0,2-((D14-D15)-D$3))) | E16: =IF(E14="","",MAX(0,2-((E14-E15)-E$3))) | F16: =IF(F14="","",MAX(0,2-((F14-F15)-F$3))) | G16: =IF(G14="","",MAX(0,2-((G14-G15)-G$3))) | H16: =IF(H14="","",MAX(0,2-((H14-H15)-H$3))) | I16: =IF(I14="","",MAX(0,2-((I14-I15)-I$3))) | J16: =IF(J14="","",MAX(0,2-((J14-J15)-J$3))) | K16: =IF(K14="","",MAX(0,2-((K14-K15)-K$3))) | L16: =SUM(C16:K16) -> 0 | M16: =IF(M14="","",MAX(0,2-((M14-M15)-M$3))) | N16: =IF(N14="","",MAX(0,2-((N14-N15)-N$3))) | O16: =IF(O14="","",MAX(0,2-((O14-O15)-O$3))) | P16: =IF(P14="","",MAX(0,2-((P14-P15)-P$3))) | Q16: =IF(Q14="","",MAX(0,2-((Q14-Q15)-Q$3))) | R16: =IF(R14="","",MAX(0,2-((R14-R15)-R$3))) | S16: =IF(S14="","",MAX(0,2-((S14-S15)-S$3))) | T16: =IF(T14="","",MAX(0,2-((T14-T15)-T$3))) | U16: =IF(U14="","",MAX(0,2-((U14-U15)-U$3))) | V16: =SUM(M16:U16) -> 0 | W16: =L16+V16 -> 0
A17: Andrew — Gross | B17: ='Course Handicaps'!F8 -> 29 | L17: =IF(COUNT(C17:K17)=0,"",SUM(C17:K17)) | V17: =IF(COUNT(M17:U17)=0,"",SUM(M17:U17)) | W17: =IF(AND(L17="",V17=""),"",SUM(L17,V17))
A18: Andrew — Strokes received | C18: =IF($B17="","",FLOOR($B17/18,1)+IF(MOD($B17,18)>=C$4,1,0)) -> 2 | D18: =IF($B17="","",FLOOR($B17/18,1)+IF(MOD($B17,18)>=D$4,1,0)) -> 2 | E18: =IF($B17="","",FLOOR($B17/18,1)+IF(MOD($B17,18)>=E$4,1,0)) -> 2 | F18: =IF($B17="","",FLOOR($B17/18,1)+IF(MOD($B17,18)>=F$4,1,0)) -> 2 | G18: =IF($B17="","",FLOOR($B17/18,1)+IF(MOD($B17,18)>=G$4,1,0)) -> 2 | H18: =IF($B17="","",FLOOR($B17/18,1)+IF(MOD($B17,18)>=H$4,1,0)) -> 2 | I18: =IF($B17="","",FLOOR($B17/18,1)+IF(MOD($B17,18)>=I$4,1,0)) -> 2 | J18: =IF($B17="","",FLOOR($B17/18,1)+IF(MOD($B17,18)>=J$4,1,0)) -> 2 | K18: =IF($B17="","",FLOOR($B17/18,1)+IF(MOD($B17,18)>=K$4,1,0)) -> 2 | L18: =IF(COUNT(C18:K18)=0,"",SUM(C18:K18)) -> 18 | M18: =IF($B17="","",FLOOR($B17/18,1)+IF(MOD($B17,18)>=M$4,1,0)) -> 2 | N18: =IF($B17="","",FLOOR($B17/18,1)+IF(MOD($B17,18)>=N$4,1,0)) -> 2 | O18: =IF($B17="","",FLOOR($B17/18,1)+IF(MOD($B17,18)>=O$4,1,0)) -> 2 | P18: =IF($B17="","",FLOOR($B17/18,1)+IF(MOD($B17,18)>=P$4,1,0)) -> 2 | Q18: =IF($B17="","",FLOOR($B17/18,1)+IF(MOD($B17,18)>=Q$4,1,0)) -> 2 | R18: =IF($B17="","",FLOOR($B17/18,1)+IF(MOD($B17,18)>=R$4,1,0)) -> 2 | S18: =IF($B17="","",FLOOR($B17/18,1)+IF(MOD($B17,18)>=S$4,1,0)) -> 2 | T18: =IF($B17="","",FLOOR($B17/18,1)+IF(MOD($B17,18)>=T$4,1,0)) -> 2 | U18: =IF($B17="","",FLOOR($B17/18,1)+IF(MOD($B17,18)>=U$4,1,0)) -> 2 | V18: =IF(COUNT(M18:U18)=0,"",SUM(M18:U18)) -> 18 | W18: =IF(AND(L18="",V18=""),"",SUM(L18,V18)) -> 36
A19: Andrew — Pts | C19: =IF(C17="","",MAX(0,2-((C17-C18)-C$3))) | D19: =IF(D17="","",MAX(0,2-((D17-D18)-D$3))) | E19: =IF(E17="","",MAX(0,2-((E17-E18)-E$3))) | F19: =IF(F17="","",MAX(0,2-((F17-F18)-F$3))) | G19: =IF(G17="","",MAX(0,2-((G17-G18)-G$3))) | H19: =IF(H17="","",MAX(0,2-((H17-H18)-H$3))) | I19: =IF(I17="","",MAX(0,2-((I17-I18)-I$3))) | J19: =IF(J17="","",MAX(0,2-((J17-J18)-J$3))) | K19: =IF(K17="","",MAX(0,2-((K17-K18)-K$3))) | L19: =SUM(C19:K19) -> 0 | M19: =IF(M17="","",MAX(0,2-((M17-M18)-M$3))) | N19: =IF(N17="","",MAX(0,2-((N17-N18)-N$3))) | O19: =IF(O17="","",MAX(0,2-((O17-O18)-O$3))) | P19: =IF(P17="","",MAX(0,2-((P17-P18)-P$3))) | Q19: =IF(Q17="","",MAX(0,2-((Q17-Q18)-Q$3))) | R19: =IF(R17="","",MAX(0,2-((R17-R18)-R$3))) | S19: =IF(S17="","",MAX(0,2-((S17-S18)-S$3))) | T19: =IF(T17="","",MAX(0,2-((T17-T18)-T$3))) | U19: =IF(U17="","",MAX(0,2-((U17-U18)-U$3))) | V19: =SUM(M19:U19) -> 0 | W19: =L19+V19 -> 0
A20: Peter — Gross | B20: ='Course Handicaps'!F9 -> 20 | L20: =IF(COUNT(C20:K20)=0,"",SUM(C20:K20)) | V20: =IF(COUNT(M20:U20)=0,"",SUM(M20:U20)) | W20: =IF(AND(L20="",V20=""),"",SUM(L20,V20))
A21: Peter — Strokes received | C21: =IF($B20="","",FLOOR($B20/18,1)+IF(MOD($B20,18)>=C$4,1,0)) -> 2 | D21: =IF($B20="","",FLOOR($B20/18,1)+IF(MOD($B20,18)>=D$4,1,0)) -> 2 | E21: =IF($B20="","",FLOOR($B20/18,1)+IF(MOD($B20,18)>=E$4,1,0)) -> 2 | F21: =IF($B20="","",FLOOR($B20/18,1)+IF(MOD($B20,18)>=F$4,1,0)) -> 2 | G21: =IF($B20="","",FLOOR($B20/18,1)+IF(MOD($B20,18)>=G$4,1,0)) -> 2 | H21: =IF($B20="","",FLOOR($B20/18,1)+IF(MOD($B20,18)>=H$4,1,0)) -> 2 | I21: =IF($B20="","",FLOOR($B20/18,1)+IF(MOD($B20,18)>=I$4,1,0)) -> 2 | J21: =IF($B20="","",FLOOR($B20/18,1)+IF(MOD($B20,18)>=J$4,1,0)) -> 2 | K21: =IF($B20="","",FLOOR($B20/18,1)+IF(MOD($B20,18)>=K$4,1,0)) -> 2 | L21: =IF(COUNT(C21:K21)=0,"",SUM(C21:K21)) -> 18 | M21: =IF($B20="","",FLOOR($B20/18,1)+IF(MOD($B20,18)>=M$4,1,0)) -> 2 | N21: =IF($B20="","",FLOOR($B20/18,1)+IF(MOD($B20,18)>=N$4,1,0)) -> 2 | O21: =IF($B20="","",FLOOR($B20/18,1)+IF(MOD($B20,18)>=O$4,1,0)) -> 2 | P21: =IF($B20="","",FLOOR($B20/18,1)+IF(MOD($B20,18)>=P$4,1,0)) -> 2 | Q21: =IF($B20="","",FLOOR($B20/18,1)+IF(MOD($B20,18)>=Q$4,1,0)) -> 2 | R21: =IF($B20="","",FLOOR($B20/18,1)+IF(MOD($B20,18)>=R$4,1,0)) -> 2 | S21: =IF($B20="","",FLOOR($B20/18,1)+IF(MOD($B20,18)>=S$4,1,0)) -> 2 | T21: =IF($B20="","",FLOOR($B20/18,1)+IF(MOD($B20,18)>=T$4,1,0)) -> 2 | U21: =IF($B20="","",FLOOR($B20/18,1)+IF(MOD($B20,18)>=U$4,1,0)) -> 2 | V21: =IF(COUNT(M21:U21)=0,"",SUM(M21:U21)) -> 18 | W21: =IF(AND(L21="",V21=""),"",SUM(L21,V21)) -> 36
A22: Peter — Pts | C22: =IF(C20="","",MAX(0,2-((C20-C21)-C$3))) | D22: =IF(D20="","",MAX(0,2-((D20-D21)-D$3))) | E22: =IF(E20="","",MAX(0,2-((E20-E21)-E$3))) | F22: =IF(F20="","",MAX(0,2-((F20-F21)-F$3))) | G22: =IF(G20="","",MAX(0,2-((G20-G21)-G$3))) | H22: =IF(H20="","",MAX(0,2-((H20-H21)-H$3))) | I22: =IF(I20="","",MAX(0,2-((I20-I21)-I$3))) | J22: =IF(J20="","",MAX(0,2-((J20-J21)-J$3))) | K22: =IF(K20="","",MAX(0,2-((K20-K21)-K$3))) | L22: =SUM(C22:K22) -> 0 | M22: =IF(M20="","",MAX(0,2-((M20-M21)-M$3))) | N22: =IF(N20="","",MAX(0,2-((N20-N21)-N$3))) | O22: =IF(O20="","",MAX(0,2-((O20-O21)-O$3))) | P22: =IF(P20="","",MAX(0,2-((P20-P21)-P$3))) | Q22: =IF(Q20="","",MAX(0,2-((Q20-Q21)-Q$3))) | R22: =IF(R20="","",MAX(0,2-((R20-R21)-R$3))) | S22: =IF(S20="","",MAX(0,2-((S20-S21)-S$3))) | T22: =IF(T20="","",MAX(0,2-((T20-T21)-T$3))) | U22: =IF(U20="","",MAX(0,2-((U20-U21)-U$3))) | V22: =SUM(M22:U22) -> 0 | W22: =L22+V22 -> 0
A23: Fraser — Gross | B23: ='Course Handicaps'!F10 -> 16 | L23: =IF(COUNT(C23:K23)=0,"",SUM(C23:K23)) | V23: =IF(COUNT(M23:U23)=0,"",SUM(M23:U23)) | W23: =IF(AND(L23="",V23=""),"",SUM(L23,V23))
A24: Fraser — Strokes received | C24: =IF($B23="","",FLOOR($B23/18,1)+IF(MOD($B23,18)>=C$4,1,0)) -> 1 | D24: =IF($B23="","",FLOOR($B23/18,1)+IF(MOD($B23,18)>=D$4,1,0)) -> 1 | E24: =IF($B23="","",FLOOR($B23/18,1)+IF(MOD($B23,18)>=E$4,1,0)) -> 1 | F24: =IF($B23="","",FLOOR($B23/18,1)+IF(MOD($B23,18)>=F$4,1,0)) -> 1 | G24: =IF($B23="","",FLOOR($B23/18,1)+IF(MOD($B23,18)>=G$4,1,0)) -> 1 | H24: =IF($B23="","",FLOOR($B23/18,1)+IF(MOD($B23,18)>=H$4,1,0)) -> 1 | I24: =IF($B23="","",FLOOR($B23/18,1)+IF(MOD($B23,18)>=I$4,1,0)) -> 1 | J24: =IF($B23="","",FLOOR($B23/18,1)+IF(MOD($B23,18)>=J$4,1,0)) -> 1 | K24: =IF($B23="","",FLOOR($B23/18,1)+IF(MOD($B23,18)>=K$4,1,0)) -> 1 | L24: =IF(COUNT(C24:K24)=0,"",SUM(C24:K24)) -> 9 | M24: =IF($B23="","",FLOOR($B23/18,1)+IF(MOD($B23,18)>=M$4,1,0)) -> 1 | N24: =IF($B23="","",FLOOR($B23/18,1)+IF(MOD($B23,18)>=N$4,1,0)) -> 1 | O24: =IF($B23="","",FLOOR($B23/18,1)+IF(MOD($B23,18)>=O$4,1,0)) -> 1 | P24: =IF($B23="","",FLOOR($B23/18,1)+IF(MOD($B23,18)>=P$4,1,0)) -> 1 | Q24: =IF($B23="","",FLOOR($B23/18,1)+IF(MOD($B23,18)>=Q$4,1,0)) -> 1 | R24: =IF($B23="","",FLOOR($B23/18,1)+IF(MOD($B23,18)>=R$4,1,0)) -> 1 | S24: =IF($B23="","",FLOOR($B23/18,1)+IF(MOD($B23,18)>=S$4,1,0)) -> 1 | T24: =IF($B23="","",FLOOR($B23/18,1)+IF(MOD($B23,18)>=T$4,1,0)) -> 1 | U24: =IF($B23="","",FLOOR($B23/18,1)+IF(MOD($B23,18)>=U$4,1,0)) -> 1 | V24: =IF(COUNT(M24:U24)=0,"",SUM(M24:U24)) -> 9 | W24: =IF(AND(L24="",V24=""),"",SUM(L24,V24)) -> 18
A25: Fraser — Pts | C25: =IF(C23="","",MAX(0,2-((C23-C24)-C$3))) | D25: =IF(D23="","",MAX(0,2-((D23-D24)-D$3))) | E25: =IF(E23="","",MAX(0,2-((E23-E24)-E$3))) | F25: =IF(F23="","",MAX(0,2-((F23-F24)-F$3))) | G25: =IF(G23="","",MAX(0,2-((G23-G24)-G$3))) | H25: =IF(H23="","",MAX(0,2-((H23-H24)-H$3))) | I25: =IF(I23="","",MAX(0,2-((I23-I24)-I$3))) | J25: =IF(J23="","",MAX(0,2-((J23-J24)-J$3))) | K25: =IF(K23="","",MAX(0,2-((K23-K24)-K$3))) | L25: =SUM(C25:K25) -> 0 | M25: =IF(M23="","",MAX(0,2-((M23-M24)-M$3))) | N25: =IF(N23="","",MAX(0,2-((N23-N24)-N$3))) | O25: =IF(O23="","",MAX(0,2-((O23-O24)-O$3))) | P25: =IF(P23="","",MAX(0,2-((P23-P24)-P$3))) | Q25: =IF(Q23="","",MAX(0,2-((Q23-Q24)-Q$3))) | R25: =IF(R23="","",MAX(0,2-((R23-R24)-R$3))) | S25: =IF(S23="","",MAX(0,2-((S23-S24)-S$3))) | T25: =IF(T23="","",MAX(0,2-((T23-T24)-T$3))) | U25: =IF(U23="","",MAX(0,2-((U23-U24)-U$3))) | V25: =SUM(M25:U25) -> 0 | W25: =L25+V25 -> 0
A26: Colin — Gross | B26: ='Course Handicaps'!F11 -> 28 | L26: =IF(COUNT(C26:K26)=0,"",SUM(C26:K26)) | V26: =IF(COUNT(M26:U26)=0,"",SUM(M26:U26)) | W26: =IF(AND(L26="",V26=""),"",SUM(L26,V26))
A27: Colin — Strokes received | C27: =IF($B26="","",FLOOR($B26/18,1)+IF(MOD($B26,18)>=C$4,1,0)) -> 2 | D27: =IF($B26="","",FLOOR($B26/18,1)+IF(MOD($B26,18)>=D$4,1,0)) -> 2 | E27: =IF($B26="","",FLOOR($B26/18,1)+IF(MOD($B26,18)>=E$4,1,0)) -> 2 | F27: =IF($B26="","",FLOOR($B26/18,1)+IF(MOD($B26,18)>=F$4,1,0)) -> 2 | G27: =IF($B26="","",FLOOR($B26/18,1)+IF(MOD($B26,18)>=G$4,1,0)) -> 2 | H27: =IF($B26="","",FLOOR($B26/18,1)+IF(MOD($B26,18)>=H$4,1,0)) -> 2 | I27: =IF($B26="","",FLOOR($B26/18,1)+IF(MOD($B26,18)>=I$4,1,0)) -> 2 | J27: =IF($B26="","",FLOOR($B26/18,1)+IF(MOD($B26,18)>=J$4,1,0)) -> 2 | K27: =IF($B26="","",FLOOR($B26/18,1)+IF(MOD($B26,18)>=K$4,1,0)) -> 2 | L27: =IF(COUNT(C27:K27)=0,"",SUM(C27:K27)) -> 18 | M27: =IF($B26="","",FLOOR($B26/18,1)+IF(MOD($B26,18)>=M$4,1,0)) -> 2 | N27: =IF($B26="","",FLOOR($B26/18,1)+IF(MOD($B26,18)>=N$4,1,0)) -> 2 | O27: =IF($B26="","",FLOOR($B26/18,1)+IF(MOD($B26,18)>=O$4,1,0)) -> 2 | P27: =IF($B26="","",FLOOR($B26/18,1)+IF(MOD($B26,18)>=P$4,1,0)) -> 2 | Q27: =IF($B26="","",FLOOR($B26/18,1)+IF(MOD($B26,18)>=Q$4,1,0)) -> 2 | R27: =IF($B26="","",FLOOR($B26/18,1)+IF(MOD($B26,18)>=R$4,1,0)) -> 2 | S27: =IF($B26="","",FLOOR($B26/18,1)+IF(MOD($B26,18)>=S$4,1,0)) -> 2 | T27: =IF($B26="","",FLOOR($B26/18,1)+IF(MOD($B26,18)>=T$4,1,0)) -> 2 | U27: =IF($B26="","",FLOOR($B26/18,1)+IF(MOD($B26,18)>=U$4,1,0)) -> 2 | V27: =IF(COUNT(M27:U27)=0,"",SUM(M27:U27)) -> 18 | W27: =IF(AND(L27="",V27=""),"",SUM(L27,V27)) -> 36
A28: Colin — Pts | C28: =IF(C26="","",MAX(0,2-((C26-C27)-C$3))) | D28: =IF(D26="","",MAX(0,2-((D26-D27)-D$3))) | E28: =IF(E26="","",MAX(0,2-((E26-E27)-E$3))) | F28: =IF(F26="","",MAX(0,2-((F26-F27)-F$3))) | G28: =IF(G26="","",MAX(0,2-((G26-G27)-G$3))) | H28: =IF(H26="","",MAX(0,2-((H26-H27)-H$3))) | I28: =IF(I26="","",MAX(0,2-((I26-I27)-I$3))) | J28: =IF(J26="","",MAX(0,2-((J26-J27)-J$3))) | K28: =IF(K26="","",MAX(0,2-((K26-K27)-K$3))) | L28: =SUM(C28:K28) -> 0 | M28: =IF(M26="","",MAX(0,2-((M26-M27)-M$3))) | N28: =IF(N26="","",MAX(0,2-((N26-N27)-N$3))) | O28: =IF(O26="","",MAX(0,2-((O26-O27)-O$3))) | P28: =IF(P26="","",MAX(0,2-((P26-P27)-P$3))) | Q28: =IF(Q26="","",MAX(0,2-((Q26-Q27)-Q$3))) | R28: =IF(R26="","",MAX(0,2-((R26-R27)-R$3))) | S28: =IF(S26="","",MAX(0,2-((S26-S27)-S$3))) | T28: =IF(T26="","",MAX(0,2-((T26-T27)-T$3))) | U28: =IF(U26="","",MAX(0,2-((U26-U27)-U$3))) | V28: =SUM(M28:U28) -> 0 | W28: =L28+V28 -> 0
A30: Yellow = fill in: Par & Stroke Index from the course scorecard, Gross = strokes per hole. Crs Hcp (green) is auto-linked from the Course Handicaps tab — update handicaps there, not here. "Strokes received" and "Pts" rows calculate automatically.

Sheet Rd2 Alt - Leven
A1: Round 2 (Alt) — Leven Links (if your group plays here instead) (Tuesday)
A2: Hole | B2: Crs Hcp | C2: 1 | D2: 2 | E2: 3 | F2: 4 | G2: 5 | H2: 6 | I2: 7 | J2: 8 | K2: 9 | L2: OUT | M2: 10 | N2: 11 | O2: 12 | P2: 13 | Q2: 14 | R2: 15 | S2: 16 | T2: 17 | U2: 18 | V2: IN | W2: TOTAL
A3: Par | L3: =SUM(C3:K3) -> 0 | V3: =SUM(M3:U3) -> 0 | W3: =L3+V3 -> 0
A4: Stroke Index
A5: Paul — Gross | L5: =IF(COUNT(C5:K5)=0,"",SUM(C5:K5)) | V5: =IF(COUNT(M5:U5)=0,"",SUM(M5:U5)) | W5: =IF(AND(L5="",V5=""),"",SUM(L5,V5))
A6: Paul — Strokes received | C6: =IF($B5="","",FLOOR($B5/18,1)+IF(MOD($B5,18)>=C$4,1,0)) | D6: =IF($B5="","",FLOOR($B5/18,1)+IF(MOD($B5,18)>=D$4,1,0)) | E6: =IF($B5="","",FLOOR($B5/18,1)+IF(MOD($B5,18)>=E$4,1,0)) | F6: =IF($B5="","",FLOOR($B5/18,1)+IF(MOD($B5,18)>=F$4,1,0)) | G6: =IF($B5="","",FLOOR($B5/18,1)+IF(MOD($B5,18)>=G$4,1,0)) | H6: =IF($B5="","",FLOOR($B5/18,1)+IF(MOD($B5,18)>=H$4,1,0)) | I6: =IF($B5="","",FLOOR($B5/18,1)+IF(MOD($B5,18)>=I$4,1,0)) | J6: =IF($B5="","",FLOOR($B5/18,1)+IF(MOD($B5,18)>=J$4,1,0)) | K6: =IF($B5="","",FLOOR($B5/18,1)+IF(MOD($B5,18)>=K$4,1,0)) | L6: =IF(COUNT(C6:K6)=0,"",SUM(C6:K6)) | M6: =IF($B5="","",FLOOR($B5/18,1)+IF(MOD($B5,18)>=M$4,1,0)) | N6: =IF($B5="","",FLOOR($B5/18,1)+IF(MOD($B5,18)>=N$4,1,0)) | O6: =IF($B5="","",FLOOR($B5/18,1)+IF(MOD($B5,18)>=O$4,1,0)) | P6: =IF($B5="","",FLOOR($B5/18,1)+IF(MOD($B5,18)>=P$4,1,0)) | Q6: =IF($B5="","",FLOOR($B5/18,1)+IF(MOD($B5,18)>=Q$4,1,0)) | R6: =IF($B5="","",FLOOR($B5/18,1)+IF(MOD($B5,18)>=R$4,1,0)) | S6: =IF($B5="","",FLOOR($B5/18,1)+IF(MOD($B5,18)>=S$4,1,0)) | T6: =IF($B5="","",FLOOR($B5/18,1)+IF(MOD($B5,18)>=T$4,1,0)) | U6: =IF($B5="","",FLOOR($B5/18,1)+IF(MOD($B5,18)>=U$4,1,0)) | V6: =IF(COUNT(M6:U6)=0,"",SUM(M6:U6)) | W6: =IF(AND(L6="",V6=""),"",SUM(L6,V6))
A7: Paul — Pts | C7: =IF(C5="","",MAX(0,2-((C5-C6)-C$3))) | D7: =IF(D5="","",MAX(0,2-((D5-D6)-D$3))) | E7: =IF(E5="","",MAX(0,2-((E5-E6)-E$3))) | F7: =IF(F5="","",MAX(0,2-((F5-F6)-F$3))) | G7: =IF(G5="","",MAX(0,2-((G5-G6)-G$3))) | H7: =IF(H5="","",MAX(0,2-((H5-H6)-H$3))) | I7: =IF(I5="","",MAX(0,2-((I5-I6)-I$3))) | J7: =IF(J5="","",MAX(0,2-((J5-J6)-J$3))) | K7: =IF(K5="","",MAX(0,2-((K5-K6)-K$3))) | L7: =SUM(C7:K7) -> 0 | M7: =IF(M5="","",MAX(0,2-((M5-M6)-M$3))) | N7: =IF(N5="","",MAX(0,2-((N5-N6)-N$3))) | O7: =IF(O5="","",MAX(0,2-((O5-O6)-O$3))) | P7: =IF(P5="","",MAX(0,2-((P5-P6)-P$3))) | Q7: =IF(Q5="","",MAX(0,2-((Q5-Q6)-Q$3))) | R7: =IF(R5="","",MAX(0,2-((R5-R6)-R$3))) | S7: =IF(S5="","",MAX(0,2-((S5-S6)-S$3))) | T7: =IF(T5="","",MAX(0,2-((T5-T6)-T$3))) | U7: =IF(U5="","",MAX(0,2-((U5-U6)-U$3))) | V7: =SUM(M7:U7) -> 0 | W7: =L7+V7 -> 0
A8: David — Gross | L8: =IF(COUNT(C8:K8)=0,"",SUM(C8:K8)) | V8: =IF(COUNT(M8:U8)=0,"",SUM(M8:U8)) | W8: =IF(AND(L8="",V8=""),"",SUM(L8,V8))
A9: David — Strokes received | C9: =IF($B8="","",FLOOR($B8/18,1)+IF(MOD($B8,18)>=C$4,1,0)) | D9: =IF($B8="","",FLOOR($B8/18,1)+IF(MOD($B8,18)>=D$4,1,0)) | E9: =IF($B8="","",FLOOR($B8/18,1)+IF(MOD($B8,18)>=E$4,1,0)) | F9: =IF($B8="","",FLOOR($B8/18,1)+IF(MOD($B8,18)>=F$4,1,0)) | G9: =IF($B8="","",FLOOR($B8/18,1)+IF(MOD($B8,18)>=G$4,1,0)) | H9: =IF($B8="","",FLOOR($B8/18,1)+IF(MOD($B8,18)>=H$4,1,0)) | I9: =IF($B8="","",FLOOR($B8/18,1)+IF(MOD($B8,18)>=I$4,1,0)) | J9: =IF($B8="","",FLOOR($B8/18,1)+IF(MOD($B8,18)>=J$4,1,0)) | K9: =IF($B8="","",FLOOR($B8/18,1)+IF(MOD($B8,18)>=K$4,1,0)) | L9: =IF(COUNT(C9:K9)=0,"",SUM(C9:K9)) | M9: =IF($B8="","",FLOOR($B8/18,1)+IF(MOD($B8,18)>=M$4,1,0)) | N9: =IF($B8="","",FLOOR($B8/18,1)+IF(MOD($B8,18)>=N$4,1,0)) | O9: =IF($B8="","",FLOOR($B8/18,1)+IF(MOD($B8,18)>=O$4,1,0)) | P9: =IF($B8="","",FLOOR($B8/18,1)+IF(MOD($B8,18)>=P$4,1,0)) | Q9: =IF($B8="","",FLOOR($B8/18,1)+IF(MOD($B8,18)>=Q$4,1,0)) | R9: =IF($B8="","",FLOOR($B8/18,1)+IF(MOD($B8,18)>=R$4,1,0)) | S9: =IF($B8="","",FLOOR($B8/18,1)+IF(MOD($B8,18)>=S$4,1,0)) | T9: =IF($B8="","",FLOOR($B8/18,1)+IF(MOD($B8,18)>=T$4,1,0)) | U9: =IF($B8="","",FLOOR($B8/18,1)+IF(MOD($B8,18)>=U$4,1,0)) | V9: =IF(COUNT(M9:U9)=0,"",SUM(M9:U9)) | W9: =IF(AND(L9="",V9=""),"",SUM(L9,V9))
A10: David — Pts | C10: =IF(C8="","",MAX(0,2-((C8-C9)-C$3))) | D10: =IF(D8="","",MAX(0,2-((D8-D9)-D$3))) | E10: =IF(E8="","",MAX(0,2-((E8-E9)-E$3))) | F10: =IF(F8="","",MAX(0,2-((F8-F9)-F$3))) | G10: =IF(G8="","",MAX(0,2-((G8-G9)-G$3))) | H10: =IF(H8="","",MAX(0,2-((H8-H9)-H$3))) | I10: =IF(I8="","",MAX(0,2-((I8-I9)-I$3))) | J10: =IF(J8="","",MAX(0,2-((J8-J9)-J$3))) | K10: =IF(K8="","",MAX(0,2-((K8-K9)-K$3))) | L10: =SUM(C10:K10) -> 0 | M10: =IF(M8="","",MAX(0,2-((M8-M9)-M$3))) | N10: =IF(N8="","",MAX(0,2-((N8-N9)-N$3))) | O10: =IF(O8="","",MAX(0,2-((O8-O9)-O$3))) | P10: =IF(P8="","",MAX(0,2-((P8-P9)-P$3))) | Q10: =IF(Q8="","",MAX(0,2-((Q8-Q9)-Q$3))) | R10: =IF(R8="","",MAX(0,2-((R8-R9)-R$3))) | S10: =IF(S8="","",MAX(0,2-((S8-S9)-S$3))) | T10: =IF(T8="","",MAX(0,2-((T8-T9)-T$3))) | U10: =IF(U8="","",MAX(0,2-((U8-U9)-U$3))) | V10: =SUM(M10:U10) -> 0 | W10: =L10+V10 -> 0
A11: Jonathan — Gross | L11: =IF(COUNT(C11:K11)=0,"",SUM(C11:K11)) | V11: =IF(COUNT(M11:U11)=0,"",SUM(M11:U11)) | W11: =IF(AND(L11="",V11=""),"",SUM(L11,V11))
